Workbook

Sheet MN layout (2x)
A1: SARS-CoV-2 MN | H1: Date of experiment: | I1: 24.05.24 | M1: Day 5 read: | N1: 29.05.24 | R1: FM
A3: Samples to test | B3: Start dil. | C3: # | D3: P | E3: D | F3: Variant
A4: High 3 | B4: 1:20 | C4: 1 | D4: 1 | E4: Dilution 1 | F4: Vic01/TMPRSS2
A5: 1678-044_pv2 | B5: 1:20 | C5: 2
A6: 1678-044_PB1 | B6: 1:20 | C6: 3 | D6: 2
A7: 1678-047_pv2 | B7: 1:20 | C7: 4
A8: 1678-047_post_v3 | B8: 1:20 | C8: 5 | D8: 3
A9: 1678-061_pv2 | B9: 1:20 | C9: 6
A10: 1678-061_post_v3 | B10: 1:20 | C10: 7 | D10: 4
A11: 1678-065_pv2 | B11: 1:20 | C11: 8
A12: 1678-065_post_v3 | B12: 1:20 | C12: 9 | D12: 5 | E12: Dilution 2 | F12: Vic01/TMPRSS2
A13: 1678-069 (008)_pv2 | B13: 1:20 | C13: 10
A14: 1678-069 (008)_M9 | B14: 1:20 | C14: 11 | D14: 6
A15: 1678-070 (043)_pv2 | B15: 1:20 | C15: 12
A16: 1678-070 (043)_post_v3 | B16: 1:20 | C16: 13 | D16: 7
A17: 1678-074_pv2 | B17: 1:20 | C17: 14
A18: 1678-074_post_v3 | B18: 1:20 | C18: 15 | D18: 8
A19: 1678-097_pv2 | B19: 1:20 | C19: 16
A20: 1678-097_post_v3 | B20: 1:20 | C20: 17 | D20: 9 | E20: Dilution 3 | F20: Vic01/TMPRSS2
A21: 1678-044(101)_post_inf_visit | B21: 1:20 | C21: 18
A22: 1678-061(117)_post_inf_visit | B22: 1:20 | C22: 19 | D22: 10
A23: 1678-066(122)_post_inf_visit | B23: 1:20 | C23: 20
A24: 1678-070(126)_post_inf_visit | B24: 1:20 | C24: 21 | D24: 11
A25: 1678-078(037)_post_inf_visit | B25: 1:20 | C25: 22
A26: 1678-090(144)_post_inf_visit | B26: 1:20 | C26: 23 | D26: 12
A27: 1678-091(145)_post_inf_visit | B27: 1:20 | C27: 24
A28: 1678-095(149)_post_inf_visit | B28: 1:20 | C28: 25 | D28: 13 | E28: Dilution 4 | F28: Vic01/TMPRSS2
A29: 1678-099(153)_post_inf_visit | B29: 1:20 | C29: 26
A30: 1678-SM_post_inf_visit | B30: 1:20 | C30: 27 | D30: 14
A31: NIBSC 21/338 | B31: 1:20 | C31: 28
A32: NIBSC 20/142 | B32: 1:20 | C32: 29 | D32: 15
A33: Neg 4 | B33: 1:20 | C33: 30
B34: 1:20 | C34: 31 | D34: 16
B35: 1:20 | C35: 32
B36: 1:20 | C36: 33 | D36: 17 | E36: Dilution 5
B37: 1:20 | C37: 34
B38: 1:20 | C38: 35 | D38: 18
B39: 1:20 | C39: 36
B40: 1:20 | C40: 37 | D40: 19
B41: 1:20 | C41: 38
...

Sheet MN protocol
A1: SARS-CoV-2 MN in Vero E6-TMPRSS2 cells
A3: Virus strain: | B3: Aus/Vic/01/2020
A4: Stock: | B4: Batch 10 - Vero P3, VeroSLAM P1 10.07.23 - S5-D-04
A5: Titre: | B5: 10^7.4 in Vero-TMPRSS2
B7: Dilution plates | C7: Cell plates
B8: 4
A9: 2x10^5 cells/ml | B9: - | C9: =C8*10 -> 0
A10: Plain MEM (dilution/cell wash) | B10: =B8*14 -> 56 | C10: =C8*20 -> 0 | D10: ml | F10: Aim for: | G10: Titre: | H10: Stock
A11: Serum-free Vero E6-TMPRSS2 media + TPCK trypsin | B11: - | C11: =C8*15 -> 0 | D11: ml | F11: 10^3.5 | G11: =G12-0.1 -> 6.2 | H11: =SUM((B12)*(10^3.5))/(10^G11) -> 0.099763116
A12: Diluted virus (100 TCID50/well) | B12: =B8*12.5 -> 50 | C12: - | D12: ml | F12: 10^3.4 | G12: =G13-0.1 -> 6.3 | H12: =SUM((B12)*(10^3.4))/(10^G12) -> 0.062946271
A13: Virus stock needed | B13: =SUM((B12)*(10^3.3))/(10^7.4) -> 0.0039716412 | C13: - | D13: ml | F13: 10^3.3 | G13: 6.4 | H13: =SUM((B12)*(10^3.3))/(10^G13) -> 0.039716412
A14: + virus media | B14: =B12-B13 -> 49.996028 | C14: - | D14: ml | F14: 10^3.2 | G14: =G13+0.1 -> 6.5 | H14: =SUM((B12)*(10^3.2))/(10^G14) -> 0.025059362
F15: 10^3.1 | G15: =G14+0.1 -> 6.6 | H15: =SUM((B12)*(10^3.1))/(10^G15) -> 0.015811388
A18: 2 days before assay: seed cells
A19: Seed 96 well plates with 1.3 x 10^5 Vero E6-TMPRSS2 cells/ml in 100 ul volume
A21: Change media on Assay cell plates
A22: Flick off growth media
A23: Add 150 ul plain MEM to each well to wash, flick off
A24: Add 150 ul serum-free DMEM + 1ug/ml TPCK trypsin/well
A25: Add 180 ul/well to back titration plate
A27: Sera setup plate
A28: Add 126 ul plain DMEM to each well
A29: Add 14 ul sera
A31: Sera dilution plate
A32: Add 125 ul plain DMEM to each well
... A47: Add 50 ul of sera dilution + virus mix to corresponding assay cell plate wells in quadruplicates
A48: Incubate at 37°C for 1 hour | E48: Note: Assay 2 Changed cells to newer Vero-TMPRSS2 passage. These were growing much slower so fewer cells seeded and confluency on day of assay was ~75% instead of 100%. Since cells got washed off a lot in initial assays when washing twice, washed only once after adsorption.
A49: Remove virus/Ab mixture using multichannel pipette.
A50: Wash with 200 ul plain MEM media.
A51: Remove MEM using multichannel pipette.
A52: Repeat wash.
A53: Replace with 200 ul serum-free media + 1ug/ml TPCK trypsin.
A54: Incubate at 37°C
A55: Read and record CPE on day 5
A56: Calculate neutralisation titre in MN results template sheet
A58: Virus back titration
A59: Add 20 ul virus dilution to column 1 of rows ABCD
A60: Serially dilute 1:10 up the plate by transferring 20 ul column to column, discarding after column 11
A61: Column 12 is the cell control
A64: Notes:

Sheet MN results 1
A1: SARS_COV_2 MN | F1: Date of experiment: | G1: ='MN layout (2x)'!I1 -> 24.05.24 | K1: Day 5 read: | L1: ='MN layout (2x)'!N1 -> 29.05.24 | P1: ='MN layout (2x)'!R1 -> FM
A3: + = CPE; - = no CPE; C = contamination assumed neg; C = contamination assumed pos; * = non-CPE rounding of cells; ? = unsure what on earth is happening | W3: DO NOT CHANGE EQUATIONS
U4: enter data | V4: enter data | X4: enter data | AC4: 4'
A5: Plate # | B5: Neut ID | C5: Sample | D5: Starting dilution | E5: 20 | F5: 40 | G5: 80 | H5: 160 | I5: 320 | J5: 640 | K5: 1280 | L5: 2560 | M5: 5120 | N5: 10240 | O5: Virus control | P5: Cell control | Q5: Count "-"s | R5: n/4 | S5: text split | U5: "0" | V5: "1" | W5: 1' | X5: "2" | Y5: 2' | Z5: 1'/2' | AA5: "4" | AB5: 3' | AC5: log10("0") | AD5: 3'+4' | AE5: 10^(3'+4') | AF5: round to 1dp | AG5: MN titre
E7: 1 | F7: 2 | G7: 3 | H7: 4 | I7: 5 | J7: 6 | K7: 7 | L7: 8 | M7: 9 | N7: 10 | O7: 11 | P7: 12 | U7: dil<50% | V7: % +ve @dil<50 | W7: 50-"1" | X7: % +ve @dil>50 | Y7: "2"-"1" | Z7: "3" | AA7: log2 | AB7: "3"*"4" | AC7: log dil<50%
A8: P1 | B8: ='MN layout (2x)'!C4 -> 1 | C8: ='MN layout (2x)'!A4 -> High 3 | D8: ='MN layout (2x)'!B4 -> 1:20 | E8: ---- | F8: ---- | G8: ---- | H8: ---- | I8: ---- | J8: ---- | K8: ++-+ | L8: ++-+ | M8: ++++ | N8: ++++ | O8: ++++ | P8: ---- | Q8: {=SUMPRODUCT(LEN(E8:N8)-LEN(SUBSTITUTE(E8:N8,"-","")))} -> 26 | R8: =Q8/4 -> 6.5 | S8: {=_xlfn.TEXTSPLIT(R8,".",)} -> 6 | T8: 5 | U8: =IF(Q8=0,10,(IF(Q8=1,10,(IF(Q8=2,20,(IF(Q8=3,20,(IF(Q8=4,20,(IF(Q8=5,20,(IF(Q8=6,40,(IF(Q8=7,40,(IF(Q8=8,40,(IF(Q8=9,40,(IF(Q8=10,80,(IF(Q8=11,80,(IF(Q8=12,80,(IF(Q8=13,80,(IF(Q8=14,160,(IF(Q8=15,160,(IF(Q8=16,160,(IF(Q8=17,160,(IF(Q8=18,320,(IF(Q8=19,320,(IF(Q8=20,320,(IF(Q8=21,320,(IF(Q8=22,640,(IF(Q8=23,640,(IF(Q8=24,640,(IF(Q8=25,640,(IF(Q8=26,1280,(IF(Q8=27,1280,(IF(Q8=28,1280,(IF(Q8=29,1280,(IF(Q8=30,2560,(IF(Q8=31,2560,(IF(Q8=32,2560,(IF(Q8=33,2560,(IF(Q8=34,5120,(IF(Q8=35,5120,(IF(Q8=36,5120,(IF(Q8=37,5120,(IF(Q8=38,10240,(IF(Q8=39,10240,(IF(Q8=40,10240,"No endpoint"))))))))))))))))))))))))))))))))))))))))))))))))))))))))))))))))))))))))))))))))) -> 1280 | V8: =IF(T8="25",0,(IF(T8="5",50,(IF(T8="75",25,0))))) -> 50 | W8: =50-V8 -> 0 | X8: =IF(T8="25",75,100) -> 100 | Y8: =X8-V8 -> 50 | Z8: =W8/Y8 -> 0 | AA8: =LOG10(2) -> 0.30103 | AB8: =Z8*AA8 -> 0 | AC8: =LOG10(U8) -> 3.10721 | AD8: =AB8+AC8 -> 3.10721 | AE8: =10^AD8 -> 1280 | AF8: =ROUND(AE8,1) -> 1280 | AG8: =IF(AF8<20,"<20",ROUND(AF8,0)) -> 1280
B9: ='MN layout (2x)'!C5 -> 2 | C9: ='MN layout (2x)'!A5 -> 1678-044_pv2 | D9: ='MN layout (2x)'!B5 -> 1:20 | E9: --+- | F9: -+-- | G9: --+- | H9: --++ | I9: ++++ | J9: ++++ | K9: ++++ | L9: ++++ | M9: ++++ | N9: ++++ | O9: ++++ | P9: ---- | Q9: {=SUMPRODUCT(LEN(E9:N9)-LEN(SUBSTITUTE(E9:N9,"-","")))} -> 11 | R9: =Q9/4 -> 2.75 | S9: {=_xlfn.TEXTSPLIT(R9,".",)} -> 2 | T9: 75 | U9: =IF(Q9=0,10,(IF(Q9=1,10,(IF(Q9=2,20,(IF(Q9=3,20,(IF(Q9=4,20,(IF(Q9=5,20,(IF(Q9=6,40,(IF(Q9=7,40,(IF(Q9=8,40,(IF(Q9=9,40,(IF(Q9=10,80,(IF(Q9=11,80,(IF(Q9=12,80,(IF(Q9=13,80,(IF(Q9=14,160,(IF(Q9=15,160,(IF(Q9=16,160,(IF(Q9=17,160,(IF(Q9=18,320,(IF(Q9=19,320,(IF(Q9=20,320,(IF(Q9=21,320,(IF(Q9=22,640,(IF(Q9=23,640,(IF(Q9=24,640,(IF(Q9=25,640,(IF(Q9=26,1280,(IF(Q9=27,1280,(IF(Q9=28,1280,(IF(Q9=29,1280,(IF(Q9=30,2560,(IF(Q9=31,2560,(IF(Q9=32,2560,(IF(Q9=33,2560,(IF(Q9=34,5120,(IF(Q9=35,5120,(IF(Q9=36,5120,(IF(Q9=37,5120,(IF(Q9=38,10240,(IF(Q9=39,10240,(IF(Q9=40,10240,"No endpoint"))))))))))))))))))))))))))))))))))))))))))))))))))))))))))))))))))))))))))))))))) -> 80 | V9: =IF(T9="25",0,(IF(T9="5",50,(IF(T9="75",25,0))))) -> 25 | W9: =50-V9 -> 25 | X9: =IF(T9="25",75,100) -> 100 | Y9: =X9-V9 -> 75 | Z9: =W9/Y9 -> 0.33333333 | AA9: =LOG10(2) -> 0.30103 | AB9: =Z9*AA9 -> 0.10034333 | AC9: =LOG10(U9) -> 1.90309 | AD9: =AB9+AC9 -> 2.0034333 | AE9: =10^AD9 -> 100.79368 | AF9: =ROUND(AE9,1) -> 100.8 | AG9: =IF(AF9<20,"<20",ROUND(AF9,0)) -> 101
A10: P2 | B10: ='MN layout (2x)'!C6 -> 3 | C10: ='MN layout (2x)'!A6 -> 1678-044_PB1 | D10: ='MN layout (2x)'!B6 -> 1:20 | E10: ---- | F10: ---- | G10: ---- | H10: ---- | I10: ---- | J10: ---+ | K10: +--+ | L10: +++- | M10: +++- | N10: ++++ | O10: ++++ | P10: ---- | Q10: {=SUMPRODUCT(LEN(E10:N10)-LEN(SUBSTITUTE(E10:N10,"-","")))} -> 27 | R10: =Q10/4 -> 6.75 | S10: {=_xlfn.TEXTSPLIT(R10,".",)} -> 6 | T10: 75 | U10: =IF(Q10=0,10,(IF(Q10=1,10,(IF(Q10=2,20,(IF(Q10=3,20,(IF(Q10=4,20,(IF(Q10=5,20,(IF(Q10=6,40,(IF(Q10=7,40,(IF(Q10=8,40,(IF(Q10=9,40,(IF(Q10=10,80,(IF(Q10=11,80,(IF(Q10=12,80,(IF(Q10=13,80,(IF(Q10=14,160,(IF(Q10=15,160,(IF(Q10=16,160,(IF(Q10=17,160,(IF(Q10=18,320,(IF(Q10=19,320,(IF(Q10=20,320,(IF(Q10=21,320,(IF(Q10=22,640,(IF(Q10=23,640,(IF(Q10=24,640,(IF(Q10=25,640,(IF(Q10=26,1280,(IF(Q10=27,1280,(IF(Q10=28,1280,(IF(Q10=29,1280,(IF(Q10=30,2560,(IF(Q10=31,2560,(IF(Q10=32,2560,(IF(Q10=33,2560,(IF(Q10=34,5120,(IF(Q10=35,5120,(IF(Q10=36,5120,(IF(Q10=37,5120,(IF(Q10=38,10240,(IF(Q10=39,10240,(IF(Q10=40,10240,"No endpoint"))))))))))))))))))))))))))))))))))))))))))))))))))))))))))))))))))))))))))))))))) -> 1280 | V10: =IF(T10="25",0,(IF(T10="5",50,(IF(T10="75",25,0))))) -> 25 | W10: =50-V10 -> 25 | X10: =IF(T10="25",75,100) -> 100 | Y10: =X10-V10 -> 75 | Z10: =W10/Y10 -> 0.33333333 | AA10: =LOG10(2) -> 0.30103 | AB10: =Z10*AA10 -> 0.10034333 | AC10: =LOG10(U10) -> 3.10721 | AD10: =AB10+AC10 -> 3.2075533 | AE10: =10^AD10 -> 1612.6989 | AF10: =ROUND(AE10,1) -> 1612.7 | AG10: =IF(AF10<20,"<20",ROUND(AF10,0)) -> 1613
B11: ='MN layout (2x)'!C7 -> 4 | C11: ='MN layout (2x)'!A7 -> 1678-047_pv2 | D11: ='MN layout (2x)'!B7 -> 1:20 | E11: ---- | F11: ---- | G11: -+-+ | H11: ---- | I11: -+-+ | J11: ++-+ | K11: ++++ | L11: ++++ | M11: ++++ | N11: ++++ | O11: ++++ | P11: ---- | Q11: {=SUMPRODUCT(LEN(E11:N11)-LEN(SUBSTITUTE(E11:N11,"-","")))} -> 17 | R11: =Q11/4 -> 4.25 | S11: {=_xlfn.TEXTSPLIT(R11,".",)} -> 4 | T11: 25 | U11: =IF(Q11=0,10,(IF(Q11=1,10,(IF(Q11=2,20,(IF(Q11=3,20,(IF(Q11=4,20,(IF(Q11=5,20,(IF(Q11=6,40,(IF(Q11=7,40,(IF(Q11=8,40,(IF(Q11=9,40,(IF(Q11=10,80,(IF(Q11=11,80,(IF(Q11=12,80,(IF(Q11=13,80,(IF(Q11=14,160,(IF(Q11=15,160,(IF(Q11=16,160,(IF(Q11=17,160,(IF(Q11=18,320,(IF(Q11=19,320,(IF(Q11=20,320,(IF(Q11=21,320,(IF(Q11=22,640,(IF(Q11=23,640,(IF(Q11=24,640,(IF(Q11=25,640,(IF(Q11=26,1280,(IF(Q11=27,1280,(IF(Q11=28,1280,(IF(Q11=29,1280,(IF(Q11=30,2560,(IF(Q11=31,2560,(IF(Q11=32,2560,(IF(Q11=33,2560,(IF(Q11=34,5120,(IF(Q11=35,5120,(IF(Q11=36,5120,(IF(Q11=37,5120,(IF(Q11=38,10240,(IF(Q11=39,10240,(IF(Q11=40,10240,"No endpoint"))))))))))))))))))))))))))))))))))))))))))))))))))))))))))))))))))))))))))))))))) -> 160 | V11: =IF(T11="25",0,(IF(T11="5",50,(IF(T11="75",25,0))))) -> 0 | W11: =50-V11 -> 50 | X11: =IF(T11="25",75,100) -> 75 | Y11: =X11-V11 -> 75 | Z11: =W11/Y11 -> 0.66666667 | AA11: =LOG10(2) -> 0.30103 | AB11: =Z11*AA11 -> 0.20068666 | AC11: =LOG10(U11) -> 2.20412 | AD11: =AB11+AC11 -> 2.4048066 | AE11: =10^AD11 -> 253.98417 | AF11: =ROUND(AE11,1) -> 254 | AG11: =IF(AF11<20,"<20",ROUND(AF11,0)) -> 254
A12: P3 | B12: ='MN layout (2x)'!C8 -> 5 | C12: ='MN layout (2x)'!A8 -> 1678-047_post_v3 | D12: ='MN layout (2x)'!B8 -> 1:20 | E12: ---- | F12: ---- | G12: ---- | H12: -+-- | I12: --++ | J12: ++++ | K12: +++- | L12: ++-+ | M12: ++++ | N12: ++++ | O12: +-++ | P12: ---- | Q12: {=SUMPRODUCT(LEN(E12:N12)-LEN(SUBSTITUTE(E12:N12,"-","")))} -> 19 | R12: =Q12/4 -> 4.75 | S12: {=_xlfn.TEXTSPLIT(R12,".",)} -> 4 | T12: 75 | U12: =IF(Q12=0,10,(IF(Q12=1,10,(IF(Q12=2,20,(IF(Q12=3,20,(IF(Q12=4,20,(IF(Q12=5,20,(IF(Q12=6,40,(IF(Q12=7,40,(IF(Q12=8,40,(IF(Q12=9,40,(IF(Q12=10,80,(IF(Q12=11,80,(IF(Q12=12,80,(IF(Q12=13,80,(IF(Q12=14,160,(IF(Q12=15,160,(IF(Q12=16,160,(IF(Q12=17,160,(IF(Q12=18,320,(IF(Q12=19,320,(IF(Q12=20,320,(IF(Q12=21,320,(IF(Q12=22,640,(IF(Q12=23,640,(IF(Q12=24,640,(IF(Q12=25,640,(IF(Q12=26,1280,(IF(Q12=27,1280,(IF(Q12=28,1280,(IF(Q12=29,1280,(IF(Q12=30,2560,(IF(Q12=31,2560,(IF(Q12=32,2560,(IF(Q12=33,2560,(IF(Q12=34,5120,(IF(Q12=35,5120,(IF(Q12=36,5120,(IF(Q12=37,5120,(IF(Q12=38,10240,(IF(Q12=39,10240,(IF(Q12=40,10240,"No endpoint"))))))))))))))))))))))))))))))))))))))))))))))))))))))))))))))))))))))))))))))))) -> 320 | V12: =IF(T12="25",0,(IF(T12="5",50,(IF(T12="75",25,0))))) -> 25 | W12: =50-V12 -> 25 | X12: =IF(T12="25",75,100) -> 100 | Y12: =X12-V12 -> 75 | Z12: =W12/Y12 -> 0.33333333 | AA12: =LOG10(2) -> 0.30103 | AB12: =Z12*AA12 -> 0.10034333 | AC12: =LOG10(U12) -> 2.50515 | AD12: =AB12+AC12 -> 2.6054933 | AE12: =10^AD12 -> 403.17474 | AF12: =ROUND(AE12,1) -> 403.2 | AG12: =IF(AF12<20,"<20",ROUND(AF12,0)) -> 403
B13: ='MN layout (2x)'!C9 -> 6 | C13: ='MN layout (2x)'!A9 -> 1678-061_pv2 | D13: ='MN layout (2x)'!B9 -> 1:20 | E13: ---- | F13: --+- | G13: +--- | H13: +-+- | I13: ++-- | J13: +-++ | K13: ++++ | L13: ++++ | M13: ++++ | N13: ++++ | O13: ++++ | P13: ---- | Q13: {=SUMPRODUCT(LEN(E13:N13)-LEN(SUBSTITUTE(E13:N13,"-","")))} -> 15 | R13: =Q13/4 -> 3.75 | S13: {=_xlfn.TEXTSPLIT(R13,".",)} -> 3 | T13: 75 | U13: =IF(Q13=0,10,(IF(Q13=1,10,(IF(Q13=2,20,(IF(Q13=3,20,(IF(Q13=4,20,(IF(Q13=5,20,(IF(Q13=6,40,(IF(Q13=7,40,(IF(Q13=8,40,(IF(Q13=9,40,(IF(Q13=10,80,(IF(Q13=11,80,(IF(Q13=12,80,(IF(Q13=13,80,(IF(Q13=14,160,(IF(Q13=15,160,(IF(Q13=16,160,(IF(Q13=17,160,(IF(Q13=18,320,(IF(Q13=19,320,(IF(Q13=20,320,(IF(Q13=21,320,(IF(Q13=22,640,(IF(Q13=23,640,(IF(Q13=24,640,(IF(Q13=25,640,(IF(Q13=26,1280,(IF(Q13=27,1280,(IF(Q13=28,1280,(IF(Q13=29,1280,(IF(Q13=30,2560,(IF(Q13=31,2560,(IF(Q13=32,2560,(IF(Q13=33,2560,(IF(Q13=34,5120,(IF(Q13=35,5120,(IF(Q13=36,5120,(IF(Q13=37,5120,(IF(Q13=38,10240,(IF(Q13=39,10240,(IF(Q13=40,10240,"No endpoint"))))))))))))))))))))))))))))))))))))))))))))))))))))))))))))))))))))))))))))))))) -> 160 | V13: =IF(T13="25",0,(IF(T13="5",50,(IF(T13="75",25,0))))) -> 25 | W13: =50-V13 -> 25 | X13: =IF(T13="25",75,100) -> 100 | Y13: =X13-V13 -> 75 | Z13: =W13/Y13 -> 0.33333333 | AA13: =LOG10(2) -> 0.30103 | AB13: =Z13*AA13 -> 0.10034333 | AC13: =LOG10(U13) -> 2.20412 | AD13: =AB13+AC13 -> 2.3044633 | AE13: =10^AD13 -> 201.58737 | AF13: =ROUND(AE13,1) -> 201.6 | AG13: =IF(AF13<20,"<20",ROUND(AF13,0)) -> 202
A14: P4 | B14: ='MN layout (2x)'!C10 -> 7 | C14: ='MN layout (2x)'!A10 -> 1678-061_post_v3 | D14: ='MN layout (2x)'!B10 -> 1:20 | E14: ---- | F14: ---- | G14: ---- | H14: ---- | I14: ---- | J14: -+-+ | K14: ++++ | L14: ++++ | M14: ++++ | N14: ++++ | O14: ++++ | P14: ---- | Q14: {=SUMPRODUCT(LEN(E14:N14)-LEN(SUBSTITUTE(E14:N14,"-","")))} -> 22 | R14: =Q14/4 -> 5.5 | S14: {=_xlfn.TEXTSPLIT(R14,".",)} -> 5 | T14: 5 | U14: =IF(Q14=0,10,(IF(Q14=1,10,(IF(Q14=2,20,(IF(Q14=3,20,(IF(Q14=4,20,(IF(Q14=5,20,(IF(Q14=6,40,(IF(Q14=7,40,(IF(Q14=8,40,(IF(Q14=9,40,(IF(Q14=10,80,(IF(Q14=11,80,(IF(Q14=12,80,(IF(Q14=13,80,(IF(Q14=14,160,(IF(Q14=15,160,(IF(Q14=16,160,(IF(Q14=17,160,(IF(Q14=18,320,(IF(Q14=19,320,(IF(Q14=20,320,(IF(Q14=21,320,(IF(Q14=22,640,(IF(Q14=23,640,(IF(Q14=24,640,(IF(Q14=25,640,(IF(Q14=26,1280,(IF(Q14=27,1280,(IF(Q14=28,1280,(IF(Q14=29,1280,(IF(Q14=30,2560,(IF(Q14=31,2560,(IF(Q14=32,2560,(IF(Q14=33,2560,(IF(Q14=34,5120,(IF(Q14=35,5120,(IF(Q14=36,5120,(IF(Q14=37,5120,(IF(Q14=38,10240,(IF(Q14=39,10240,(IF(Q14=40,10240,"No endpoint"))))))))))))))))))))))))))))))))))))))))))))))))))))))))))))))))))))))))))))))))) -> 640 | V14: =IF(T14="25",0,(IF(T14="5",50,(IF(T14="75",25,0))))) -> 50 | W14: =50-V14 -> 0 | X14: =IF(T14="25",75,100) -> 100 | Y14: =X14-V14 -> 50 | Z14: =W14/Y14 -> 0 | AA14: =LOG10(2) -> 0.30103 | AB14: =Z14*AA14 -> 0 | AC14: =LOG10(U14) -> 2.80618 | AD14: =AB14+AC14 -> 2.80618 | AE14: =10^AD14 -> 640 | AF14: =ROUND(AE14,1) -> 640 | AG14: =IF(AF14<20,"<20",ROUND(AF14,0)) -> 640
B15: ='MN layout (2x)'!C11 -> 8 | C15: ='MN layout (2x)'!A11 -> 1678-065_pv2 | D15: ='MN layout (2x)'!B11 -> 1:20 | E15: ---- | F15: +--- | G15: +--+ | H15: -+-- | I15: +--+ | J15: ++++ | K15: ++++ | L15: ++++ | M15: ++++ | N15: ++++ | O15: -+++ | P15: ---- | Q15: {=SUMPRODUCT(LEN(E15:N15)-LEN(SUBSTITUTE(E15:N15,"-","")))} -> 14 | R15: =Q15/4 -> 3.5 | S15: {=_xlfn.TEXTSPLIT(R15,".",)} -> 3 | T15: 5 | U15: =IF(Q15=0,10,(IF(Q15=1,10,(IF(Q15=2,20,(IF(Q15=3,20,(IF(Q15=4,20,(IF(Q15=5,20,(IF(Q15=6,40,(IF(Q15=7,40,(IF(Q15=8,40,(IF(Q15=9,40,(IF(Q15=10,80,(IF(Q15=11,80,(IF(Q15=12,80,(IF(Q15=13,80,(IF(Q15=14,160,(IF(Q15=15,160,(IF(Q15=16,160,(IF(Q15=17,160,(IF(Q15=18,320,(IF(Q15=19,320,(IF(Q15=20,320,(IF(Q15=21,320,(IF(Q15=22,640,(IF(Q15=23,640,(IF(Q15=24,640,(IF(Q15=25,640,(IF(Q15=26,1280,(IF(Q15=27,1280,(IF(Q15=28,1280,(IF(Q15=29,1280,(IF(Q15=30,2560,(IF(Q15=31,2560,(IF(Q15=32,2560,(IF(Q15=33,2560,(IF(Q15=34,5120,(IF(Q15=35,5120,(IF(Q15=36,5120,(IF(Q15=37,5120,(IF(Q15=38,10240,(IF(Q15=39,10240,(IF(Q15=40,10240,"No endpoint"))))))))))))))))))))))))))))))))))))))))))))))))))))))))))))))))))))))))))))))))) -> 160 | V15: =IF(T15="25",0,(IF(T15="5",50,(IF(T15="75",25,0))))) -> 50 | W15: =50-V15 -> 0 | X15: =IF(T15="25",75,100) -> 100 | Y15: =X15-V15 -> 50 | Z15: =W15/Y15 -> 0 | AA15: =LOG10(2) -> 0.30103 | AB15: =Z15*AA15 -> 0 | AC15: =LOG10(U15) -> 2.20412 | AD15: =AB15+AC15 -> 2.20412 | AE15: =10^AD15 -> 160 | AF15: =ROUND(AE15,1) -> 160 | AG15: =IF(AF15<20,"<20",ROUND(AF15,0)) -> 160
A16: P5 | B16: ='MN layout (2x)'!C12 -> 9 | C16: ='MN layout (2x)'!A12 -> 1678-065_post_v3 | D16: ='MN layout (2x)'!B12 -> 1:20 | E16: ---- | F16: ---- | G16: ---- | H16: ---- | I16: -+-- | J16: ---- | K16: +-+- | L16: ++++ | M16: ++++ | N16: ++++ | O16: ++++ | P16: ---- | Q16: {=SUMPRODUCT(LEN(E16:N16)-LEN(SUBSTITUTE(E16:N16,"-","")))} -> 25 | R16: =Q16/4 -> 6.25 | S16: {=_xlfn.TEXTSPLIT(R16,".",)} -> 6 | T16: 25 | U16: =IF(Q16=0,10,(IF(Q16=1,10,(IF(Q16=2,20,(IF(Q16=3,20,(IF(Q16=4,20,(IF(Q16=5,20,(IF(Q16=6,40,(IF(Q16=7,40,(IF(Q16=8,40,(IF(Q16=9,40,(IF(Q16=10,80,(IF(Q16=11,80,(IF(Q16=12,80,(IF(Q16=13,80,(IF(Q16=14,160,(IF(Q16=15,160,(IF(Q16=16,160,(IF(Q16=17,160,(IF(Q16=18,320,(IF(Q16=19,320,(IF(Q16=20,320,(IF(Q16=21,320,(IF(Q16=22,640,(IF(Q16=23,640,(IF(Q16=24,640,(IF(Q16=25,640,(IF(Q16=26,1280,(IF(Q16=27,1280,(IF(Q16=28,1280,(IF(Q16=29,1280,(IF(Q16=30,2560,(IF(Q16=31,2560,(IF(Q16=32,2560,(IF(Q16=33,2560,(IF(Q16=34,5120,(IF(Q16=35,5120,(IF(Q16=36,5120,(IF(Q16=37,5120,(IF(Q16=38,10240,(IF(Q16=39,10240,(IF(Q16=40,10240,"No endpoint"))))))))))))))))))))))))))))))))))))))))))))))))))))))))))))))))))))))))))))))))) -> 640 | V16: =IF(T16="25",0,(IF(T16="5",50,(IF(T16="75",25,0))))) -> 0 | W16: =50-V16 -> 50 | X16: =IF(T16="25",75,100) -> 75 | Y16: =X16-V16 -> 75 | Z16: =W16/Y16 -> 0.66666667 | AA16: =LOG10(2) -> 0.30103 | AB16: =Z16*AA16 -> 0.20068666 | AC16: =LOG10(U16) -> 2.80618 | AD16: =AB16+AC16 -> 3.0068666 | AE16: =10^AD16 -> 1015.9367 | AF16: =ROUND(AE16,1) -> 1015.9 | AG16: =IF(AF16<20,"<20",ROUND(AF16,0)) -> 1016
B17: ='MN layout (2x)'!C13 -> 10 | C17: ='MN layout (2x)'!A13 -> 1678-069 (008)_pv2 | D17: ='MN layout (2x)'!B13 -> 1:20 | E17: --+- | F17: +--- | G17: --+- | H17: +--- | I17: +++- | J17: -++- | K17: ++++ | L17: ++++ | M17: ++++ | N17: ++++ | O17: ++++ | P17: ---- | Q17: {=SUMPRODUCT(LEN(E17:N17)-LEN(SUBSTITUTE(E17:N17,"-","")))} -> 15 | R17: =Q17/4 -> 3.75 | S17: {=_xlfn.TEXTSPLIT(R17,".",)} -> 3 | T17: 75 | U17: =IF(Q17=0,10,(IF(Q17=1,10,(IF(Q17=2,20,(IF(Q17=3,20,(IF(Q17=4,20,(IF(Q17=5,20,(IF(Q17=6,40,(IF(Q17=7,40,(IF(Q17=8,40,(IF(Q17=9,40,(IF(Q17=10,80,(IF(Q17=11,80,(IF(Q17=12,80,(IF(Q17=13,80,(IF(Q17=14,160,(IF(Q17=15,160,(IF(Q17=16,160,(IF(Q17=17,160,(IF(Q17=18,320,(IF(Q17=19,320,(IF(Q17=20,320,(IF(Q17=21,320,(IF(Q17=22,640,(IF(Q17=23,640,(IF(Q17=24,640,(IF(Q17=25,640,(IF(Q17=26,1280,(IF(Q17=27,1280,(IF(Q17=28,1280,(IF(Q17=29,1280,(IF(Q17=30,2560,(IF(Q17=31,2560,(IF(Q17=32,2560,(IF(Q17=33,2560,(IF(Q17=34,5120,(IF(Q17=35,5120,(IF(Q17=36,5120,(IF(Q17=37,5120,(IF(Q17=38,10240,(IF(Q17=39,10240,(IF(Q17=40,10240,"No endpoint"))))))))))))))))))))))))))))))))))))))))))))))))))))))))))))))))))))))))))))))))) -> 160 | V17: =IF(T17="25",0,(IF(T17="5",50,(IF(T17="75",25,0))))) -> 25 | W17: =50-V17 -> 25 | X17: =IF(T17="25",75,100) -> 100 | Y17: =X17-V17 -> 75 | Z17: =W17/Y17 -> 0.33333333 | AA17: =LOG10(2) -> 0.30103 | AB17: =Z17*AA17 -> 0.10034333 | AC17: =LOG10(U17) -> 2.20412 | AD17: =AB17+AC17 -> 2.3044633 | AE17: =10^AD17 -> 201.58737 | AF17: =ROUND(AE17,1) -> 201.6 | AG17: =IF(AF17<20,"<20",ROUND(AF17,0)) -> 202
A18: P6 | B18: ='MN layout (2x)'!C14 -> 11 | C18: ='MN layout (2x)'!A14 -> 1678-069 (008)_M9 | D18: ='MN layout (2x)'!B14 -> 1:20 | E18: ---- | F18: ++-+ | G18: ---- | H18: ++++ | I18: -+++ | J18: -+++ | K18: ++++ | L18: ++++ | M18: ++++ | N18: ++++ | O18: ++++ | P18: ---- | Q18: {=SUMPRODUCT(LEN(E18:N18)-LEN(SUBSTITUTE(E18:N18,"-","")))} -> 11 | R18: =Q18/4 -> 2.75 | S18: {=_xlfn.TEXTSPLIT(R18,".",)} -> 2 | T18: 75 | U18: =IF(Q18=0,10,(IF(Q18=1,10,(IF(Q18=2,20,(IF(Q18=3,20,(IF(Q18=4,20,(IF(Q18=5,20,(IF(Q18=6,40,(IF(Q18=7,40,(IF(Q18=8,40,(IF(Q18=9,40,(IF(Q18=10,80,(IF(Q18=11,80,(IF(Q18=12,80,(IF(Q18=13,80,(IF(Q18=14,160,(IF(Q18=15,160,(IF(Q18=16,160,(IF(Q18=17,160,(IF(Q18=18,320,(IF(Q18=19,320,(IF(Q18=20,320,(IF(Q18=21,320,(IF(Q18=22,640,(IF(Q18=23,640,(IF(Q18=24,640,(IF(Q18=25,640,(IF(Q18=26,1280,(IF(Q18=27,1280,(IF(Q18=28,1280,(IF(Q18=29,1280,(IF(Q18=30,2560,(IF(Q18=31,2560,(IF(Q18=32,2560,(IF(Q18=33,2560,(IF(Q18=34,5120,(IF(Q18=35,5120,(IF(Q18=36,5120,(IF(Q18=37,5120,(IF(Q18=38,10240,(IF(Q18=39,10240,(IF(Q18=40,10240,"No endpoint"))))))))))))))))))))))))))))))))))))))))))))))))))))))))))))))))))))))))))))))))) -> 80 | V18: =IF(T18="25",0,(IF(T18="5",50,(IF(T18="75",25,0))))) -> 25 | W18: =50-V18 -> 25 | X18: =IF(T18="25",75,100) -> 100 | Y18: =X18-V18 -> 75 | Z18: =W18/Y18 -> 0.33333333 | AA18: =LOG10(2) -> 0.30103 | AB18: =Z18*AA18 -> 0.10034333 | AC18: =LOG10(U18) -> 1.90309 | AD18: =AB18+AC18 -> 2.0034333 | AE18: =10^AD18 -> 100.79368 | AF18: =ROUND(AE18,1) -> 100.8 | AG18: =IF(AF18<20,"<20",ROUND(AF18,0)) -> 101
B19: ='MN layout (2x)'!C15 -> 12 | C19: ='MN layout (2x)'!A15 -> 1678-070 (043)_pv2 | D19: ='MN layout (2x)'!B15 -> 1:20 | E19: -+-- | F19: ---- | G19: --+- | H19: +--+ | I19: -++- | J19: +++- | K19: ++++ | L19: ++++ | M19: ++++ | N19: ++++ | O19: ++++ | P19: ---- | Q19: {=SUMPRODUCT(LEN(E19:N19)-LEN(SUBSTITUTE(E19:N19,"-","")))} -> 15 | R19: =Q19/4 -> 3.75 | S19: {=_xlfn.TEXTSPLIT(R19,".",)} -> 3 | T19: 75 | U19: =IF(Q19=0,10,(IF(Q19=1,10,(IF(Q19=2,20,(IF(Q19=3,20,(IF(Q19=4,20,(IF(Q19=5,20,(IF(Q19=6,40,(IF(Q19=7,40,(IF(Q19=8,40,(IF(Q19=9,40,(IF(Q19=10,80,(IF(Q19=11,80,(IF(Q19=12,80,(IF(Q19=13,80,(IF(Q19=14,160,(IF(Q19=15,160,(IF(Q19=16,160,(IF(Q19=17,160,(IF(Q19=18,320,(IF(Q19=19,320,(IF(Q19=20,320,(IF(Q19=21,320,(IF(Q19=22,640,(IF(Q19=23,640,(IF(Q19=24,640,(IF(Q19=25,640,(IF(Q19=26,1280,(IF(Q19=27,1280,(IF(Q19=28,1280,(IF(Q19=29,1280,(IF(Q19=30,2560,(IF(Q19=31,2560,(IF(Q19=32,2560,(IF(Q19=33,2560,(IF(Q19=34,5120,(IF(Q19=35,5120,(IF(Q19=36,5120,(IF(Q19=37,5120,(IF(Q19=38,10240,(IF(Q19=39,10240,(IF(Q19=40,10240,"No endpoint"))))))))))))))))))))))))))))))))))))))))))))))))))))))))))))))))))))))))))))))))) -> 160 | V19: =IF(T19="25",0,(IF(T19="5",50,(IF(T19="75",25,0))))) -> 25 | W19: =50-V19 -> 25 | X19: =IF(T19="25",75,100) -> 100 | Y19: =X19-V19 -> 75 | Z19: =W19/Y19 -> 0.33333333 | AA19: =LOG10(2) -> 0.30103 | AB19: =Z19*AA19 -> 0.10034333 | AC19: =LOG10(U19) -> 2.20412 | AD19: =AB19+AC19 -> 2.3044633 | AE19: =10^AD19 -> 201.58737 | AF19: =ROUND(AE19,1) -> 201.6 | AG19: =IF(AF19<20,"<20",ROUND(AF19,0)) -> 202
A20: P7 | B20: ='MN layout (2x)'!C16 -> 13 | C20: ='MN layout (2x)'!A16 -> 1678-070 (043)_post_v3 | D20: ='MN layout (2x)'!B16 -> 1:20 | E20: ---- | F20: ---- | G20: ---- | H20: ---- | I20: ---- | J20: +-+- | K20: +--+ | L20: ++-+ | M20: ++++ | N20: ++++ | O20: ++++ | P20: ---- | Q20: {=SUMPRODUCT(LEN(E20:N20)-LEN(SUBSTITUTE(E20:N20,"-","")))} -> 25 | R20: =Q20/4 -> 6.25 | S20: {=_xlfn.TEXTSPLIT(R20,".",)} -> 6 | T20: 25 | U20: =IF(Q20=0,10,(IF(Q20=1,10,(IF(Q20=2,20,(IF(Q20=3,20,(IF(Q20=4,20,(IF(Q20=5,20,(IF(Q20=6,40,(IF(Q20=7,40,(IF(Q20=8,40,(IF(Q20=9,40,(IF(Q20=10,80,(IF(Q20=11,80,(IF(Q20=12,80,(IF(Q20=13,80,(IF(Q20=14,160,(IF(Q20=15,160,(IF(Q20=16,160,(IF(Q20=17,160,(IF(Q20=18,320,(IF(Q20=19,320,(IF(Q20=20,320,(IF(Q20=21,320,(IF(Q20=22,640,(IF(Q20=23,640,(IF(Q20=24,640,(IF(Q20=25,640,(IF(Q20=26,1280,(IF(Q20=27,1280,(IF(Q20=28,1280,(IF(Q20=29,1280,(IF(Q20=30,2560,(IF(Q20=31,2560,(IF(Q20=32,2560,(IF(Q20=33,2560,(IF(Q20=34,5120,(IF(Q20=35,5120,(IF(Q20=36,5120,(IF(Q20=37,5120,(IF(Q20=38,10240,(IF(Q20=39,10240,(IF(Q20=40,10240,"No endpoint"))))))))))))))))))))))))))))))))))))))))))))))))))))))))))))))))))))))))))))))))) -> 640 | V20: =IF(T20="25",0,(IF(T20="5",50,(IF(T20="75",25,0))))) -> 0 | W20: =50-V20 -> 50 | X20: =IF(T20="25",75,100) -> 75 | Y20: =X20-V20 -> 75 | Z20: =W20/Y20 -> 0.66666667 | AA20: =LOG10(2) -> 0.30103 | AB20: =Z20*AA20 -> 0.20068666 | AC20: =LOG10(U20) -> 2.80618 | AD20: =AB20+AC20 -> 3.0068666 | AE20: =10^AD20 -> 1015.9367 | AF20: =ROUND(AE20,1) -> 1015.9 | AG20: =IF(AF20<20,"<20",ROUND(AF20,0)) -> 1016
B21: ='MN layout (2x)'!C17 -> 14 | C21: ='MN layout (2x)'!A17 -> 1678-074_pv2 | D21: ='MN layout (2x)'!B17 -> 1:20 | E21: +--- | F21: -+-- | G21: ++-+ | H21: ++++ | I21: +++- | J21: ++++ | K21: ++++ | L21: ++++ | M21: ++++ | N21: ++++ | O21: ++++ | P21: ---- | Q21: {=SUMPRODUCT(LEN(E21:N21)-LEN(SUBSTITUTE(E21:N21,"-","")))} -> 8 | R21: =Q21/4 -> 2 | S21: {=_xlfn.TEXTSPLIT(R21,".",)} -> 2 | U21: =IF(Q21=0,10,(IF(Q21=1,10,(IF(Q21=2,20,(IF(Q21=3,20,(IF(Q21=4,20,(IF(Q21=5,20,(IF(Q21=6,40,(IF(Q21=7,40,(IF(Q21=8,40,(IF(Q21=9,40,(IF(Q21=10,80,(IF(Q21=11,80,(IF(Q21=12,80,(IF(Q21=13,80,(IF(Q21=14,160,(IF(Q21=15,160,(IF(Q21=16,160,(IF(Q21=17,160,(IF(Q21=18,320,(IF(Q21=19,320,(IF(Q21=20,320,(IF(Q21=21,320,(IF(Q21=22,640,(IF(Q21=23,640,(IF(Q21=24,640,(IF(Q21=25,640,(IF(Q21=26,1280,(IF(Q21=27,1280,(IF(Q21=28,1280,(IF(Q21=29,1280,(IF(Q21=30,2560,(IF(Q21=31,2560,(IF(Q21=32,2560,(IF(Q21=33,2560,(IF(Q21=34,5120,(IF(Q21=35,5120,(IF(Q21=36,5120,(IF(Q21=37,5120,(IF(Q21=38,10240,(IF(Q21=39,10240,(IF(Q21=40,10240,"No endpoint"))))))))))))))))))))))))))))))))))))))))))))))))))))))))))))))))))))))))))))))))) -> 40 | V21: =IF(T21="25",0,(IF(T21="5",50,(IF(T21="75",25,0))))) -> 0 | W21: =50-V21 -> 50 | X21: =IF(T21="25",75,100) -> 100 | Y21: =X21-V21 -> 100 | Z21: =W21/Y21 -> 0.5 | AA21: =LOG10(2) -> 0.30103 | AB21: =Z21*AA21 -> 0.150515 | AC21: =LOG10(U21) -> 1.60206 | AD21: =AB21+AC21 -> 1.752575 | AE21: =10^AD21 -> 56.568542 | AF21: =ROUND(AE21,1) -> 56.6 | AG21: =IF(AF21<20,"<20",ROUND(AF21,0)) -> 57
A22: P8 | B22: ='MN layout (2x)'!C18 -> 15 | C22: ='MN layout (2x)'!A18 -> 1678-074_post_v3 | D22: ='MN layout (2x)'!B18 -> 1:20 | E22: ---- | F22: ---- | G22: ---- | H22: ---- | I22: ---- | J22: --+- | K22: ---+ | L22: --++ | M22: ++++ | N22: ++++ | O22: ++++ | P22: ---- | Q22: {=SUMPRODUCT(LEN(E22:N22)-LEN(SUBSTITUTE(E22:N22,"-","")))} -> 28 | R22: =Q22/4 -> 7 | S22: {=_xlfn.TEXTSPLIT(R22,".",)} -> 7 | U22: =IF(Q22=0,10,(IF(Q22=1,10,(IF(Q22=2,20,(IF(Q22=3,20,(IF(Q22=4,20,(IF(Q22=5,20,(IF(Q22=6,40,(IF(Q22=7,40,(IF(Q22=8,40,(IF(Q22=9,40,(IF(Q22=10,80,(IF(Q22=11,80,(IF(Q22=12,80,(IF(Q22=13,80,(IF(Q22=14,160,(IF(Q22=15,160,(IF(Q22=16,160,(IF(Q22=17,160,(IF(Q22=18,320,(IF(Q22=19,320,(IF(Q22=20,320,(IF(Q22=21,320,(IF(Q22=22,640,(IF(Q22=23,640,(IF(Q22=24,640,(IF(Q22=25,640,(IF(Q22=26,1280,(IF(Q22=27,1280,(IF(Q22=28,1280,(IF(Q22=29,1280,(IF(Q22=30,2560,(IF(Q22=31,2560,(IF(Q22=32,2560,(IF(Q22=33,2560,(IF(Q22=34,5120,(IF(Q22=35,5120,(IF(Q22=36,5120,(IF(Q22=37,5120,(IF(Q22=38,10240,(IF(Q22=39,10240,(IF(Q22=40,10240,"No endpoint"))))))))))))))))))))))))))))))))))))))))))))))))))))))))))))))))))))))))))))))))) -> 1280 | V22: =IF(T22="25",0,(IF(T22="5",50,(IF(T22="75",25,0))))) -> 0 | W22: =50-V22 -> 50 | X22: =IF(T22="25",75,100) -> 100 | Y22: =X22-V22 -> 100 | Z22: =W22/Y22 -> 0.5 | AA22: =LOG10(2) -> 0.30103 | AB22: =Z22*AA22 -> 0.150515 | AC22: =LOG10(U22) -> 3.10721 | AD22: =AB22+AC22 -> 3.257725 | AE22: =10^AD22 -> 1810.1934 | AF22: =ROUND(AE22,1) -> 1810.2 | AG22: =IF(AF22<20,"<20",ROUND(AF22,0)) -> 1810
B23: ='MN layout (2x)'!C19 -> 16 | C23: ='MN layout (2x)'!A19 -> 1678-097_pv2 | D23: ='MN layout (2x)'!B19 -> 1:20 | E23: ---- | F23: ---- | G23: ---+ | H23: ---- | I23: -+-- | J23: ++++ | K23: ++++ | L23: +++- | M23: ++++ | N23: ++++ | O23: ++++ | P23: ---- | Q23: {=SUMPRODUCT(LEN(E23:N23)-LEN(SUBSTITUTE(E23:N23,"-","")))} -> 19 | R23: =Q23/4 -> 4.75 | S23: {=_xlfn.TEXTSPLIT(R23,".",)} -> 4 | T23: 75 | U23: =IF(Q23=0,10,(IF(Q23=1,10,(IF(Q23=2,20,(IF(Q23=3,20,(IF(Q23=4,20,(IF(Q23=5,20,(IF(Q23=6,40,(IF(Q23=7,40,(IF(Q23=8,40,(IF(Q23=9,40,(IF(Q23=10,80,(IF(Q23=11,80,(IF(Q23=12,80,(IF(Q23=13,80,(IF(Q23=14,160,(IF(Q23=15,160,(IF(Q23=16,160,(IF(Q23=17,160,(IF(Q23=18,320,(IF(Q23=19,320,(IF(Q23=20,320,(IF(Q23=21,320,(IF(Q23=22,640,(IF(Q23=23,640,(IF(Q23=24,640,(IF(Q23=25,640,(IF(Q23=26,1280,(IF(Q23=27,1280,(IF(Q23=28,1280,(IF(Q23=29,1280,(IF(Q23=30,2560,(IF(Q23=31,2560,(IF(Q23=32,2560,(IF(Q23=33,2560,(IF(Q23=34,5120,(IF(Q23=35,5120,(IF(Q23=36,5120,(IF(Q23=37,5120,(IF(Q23=38,10240,(IF(Q23=39,10240,(IF(Q23=40,10240,"No endpoint"))))))))))))))))))))))))))))))))))))))))))))))))))))))))))))))))))))))))))))))))) -> 320 | V23: =IF(T23="25",0,(IF(T23="5",50,(IF(T23="75",25,0))))) -> 25 | W23: =50-V23 -> 25 | X23: =IF(T23="25",75,100) -> 100 | Y23: =X23-V23 -> 75 | Z23: =W23/Y23 -> 0.33333333 | AA23: =LOG10(2) -> 0.30103 | AB23: =Z23*AA23 -> 0.10034333 | AC23: =LOG10(U23) -> 2.50515 | AD23: =AB23+AC23 -> 2.6054933 | AE23: =10^AD23 -> 403.17474 | AF23: =ROUND(AE23,1) -> 403.2 | AG23: =IF(AF23<20,"<20",ROUND(AF23,0)) -> 403
A24: P9 | B24: ='MN layout (2x)'!C20 -> 17 | C24: ='MN layout (2x)'!A20 -> 1678-097_post_v3 | D24: ='MN layout (2x)'!B20 -> 1:20 | E24: ---- | F24: ---- | G24: ---- | H24: ---- | I24: +--+ | J24: +++- | K24: -+++ | L24: ++++ | M24: ++++ | N24: +-++ | O24: ++++ | P24: ---- | Q24: {=SUMPRODUCT(LEN(E24:N24)-LEN(SUBSTITUTE(E24:N24,"-","")))} -> 21 | R24: =Q24/4 -> 5.25 | S24: {=_xlfn.TEXTSPLIT(R24,".",)} -> 5 | T24: 25 | U24: =IF(Q24=0,10,(IF(Q24=1,10,(IF(Q24=2,20,(IF(Q24=3,20,(IF(Q24=4,20,(IF(Q24=5,20,(IF(Q24=6,40,(IF(Q24=7,40,(IF(Q24=8,40,(IF(Q24=9,40,(IF(Q24=10,80,(IF(Q24=11,80,(IF(Q24=12,80,(IF(Q24=13,80,(IF(Q24=14,160,(IF(Q24=15,160,(IF(Q24=16,160,(IF(Q24=17,160,(IF(Q24=18,320,(IF(Q24=19,320,(IF(Q24=20,320,(IF(Q24=21,320,(IF(Q24=22,640,(IF(Q24=23,640,(IF(Q24=24,640,(IF(Q24=25,640,(IF(Q24=26,1280,(IF(Q24=27,1280,(IF(Q24=28,1280,(IF(Q24=29,1280,(IF(Q24=30,2560,(IF(Q24=31,2560,(IF(Q24=32,2560,(IF(Q24=33,2560,(IF(Q24=34,5120,(IF(Q24=35,5120,(IF(Q24=36,5120,(IF(Q24=37,5120,(IF(Q24=38,10240,(IF(Q24=39,10240,(IF(Q24=40,10240,"No endpoint"))))))))))))))))))))))))))))))))))))))))))))))))))))))))))))))))))))))))))))))))) -> 320 | V24: =IF(T24="25",0,(IF(T24="5",50,(IF(T24="75",25,0))))) -> 0 | W24: =50-V24 -> 50 | X24: =IF(T24="25",75,100) -> 75 | Y24: =X24-V24 -> 75 | Z24: =W24/Y24 -> 0.66666667 | AA24: =LOG10(2) -> 0.30103 | AB24: =Z24*AA24 -> 0.20068666 | AC24: =LOG10(U24) -> 2.50515 | AD24: =AB24+AC24 -> 2.7058366 | AE24: =10^AD24 -> 507.96834 | AF24: =ROUND(AE24,1) -> 508 | AG24: =IF(AF24<20,"<20",ROUND(AF24,0)) -> 508
B25: ='MN layout (2x)'!C21 -> 18 | C25: ='MN layout (2x)'!A21 -> 1678-044(101)_post_inf_visit | D25: ='MN layout (2x)'!B21 -> 1:20 | E25: ---- | F25: ---- | G25: ---- | H25: ---- | I25: ---- | J25: +--- | K25: -+++ | L25: ++++ | M25: ++++ | N25: +++- | O25: ++++ | P25: ---- | Q25: {=SUMPRODUCT(LEN(E25:N25)-LEN(SUBSTITUTE(E25:N25,"-","")))} -> 25 | R25: =Q25/4 -> 6.25 | S25: {=_xlfn.TEXTSPLIT(R25,".",)} -> 6 | T25: 25 | U25: =IF(Q25=0,10,(IF(Q25=1,10,(IF(Q25=2,20,(IF(Q25=3,20,(IF(Q25=4,20,(IF(Q25=5,20,(IF(Q25=6,40,(IF(Q25=7,40,(IF(Q25=8,40,(IF(Q25=9,40,(IF(Q25=10,80,(IF(Q25=11,80,(IF(Q25=12,80,(IF(Q25=13,80,(IF(Q25=14,160,(IF(Q25=15,160,(IF(Q25=16,160,(IF(Q25=17,160,(IF(Q25=18,320,(IF(Q25=19,320,(IF(Q25=20,320,(IF(Q25=21,320,(IF(Q25=22,640,(IF(Q25=23,640,(IF(Q25=24,640,(IF(Q25=25,640,(IF(Q25=26,1280,(IF(Q25=27,1280,(IF(Q25=28,1280,(IF(Q25=29,1280,(IF(Q25=30,2560,(IF(Q25=31,2560,(IF(Q25=32,2560,(IF(Q25=33,2560,(IF(Q25=34,5120,(IF(Q25=35,5120,(IF(Q25=36,5120,(IF(Q25=37,5120,(IF(Q25=38,10240,(IF(Q25=39,10240,(IF(Q25=40,10240,"No endpoint"))))))))))))))))))))))))))))))))))))))))))))))))))))))))))))))))))))))))))))))))) -> 640 | V25: =IF(T25="25",0,(IF(T25="5",50,(IF(T25="75",25,0))))) -> 0 | W25: =50-V25 -> 50 | X25: =IF(T25="25",75,100) -> 75 | Y25: =X25-V25 -> 75 | Z25: =W25/Y25 -> 0.66666667 | AA25: =LOG10(2) -> 0.30103 | AB25: =Z25*AA25 -> 0.20068666 | AC25: =LOG10(U25) -> 2.80618 | AD25: =AB25+AC25 -> 3.0068666 | AE25: =10^AD25 -> 1015.9367 | AF25: =ROUND(AE25,1) -> 1015.9 | AG25: =IF(AF25<20,"<20",ROUND(AF25,0)) -> 1016
A26: P10 | B26: ='MN layout (2x)'!C22 -> 19 | C26: ='MN layout (2x)'!A22 -> 1678-061(117)_post_inf_visit | D26: ='MN layout (2x)'!B22 -> 1:20 | E26: ---- | F26: ---- | G26: ---- | H26: ---+ | I26: ---- | J26: ---+ | K26: ++++ | L26: ++++ | M26: ++++ | N26: ++++ | O26: ++++ | P26: ---- | Q26: {=SUMPRODUCT(LEN(E26:N26)-LEN(SUBSTITUTE(E26:N26,"-","")))} -> 22 | R26: =Q26/4 -> 5.5 | S26: {=_xlfn.TEXTSPLIT(R26,".",)} -> 5 | T26: 5 | U26: =IF(Q26=0,10,(IF(Q26=1,10,(IF(Q26=2,20,(IF(Q26=3,20,(IF(Q26=4,20,(IF(Q26=5,20,(IF(Q26=6,40,(IF(Q26=7,40,(IF(Q26=8,40,(IF(Q26=9,40,(IF(Q26=10,80,(IF(Q26=11,80,(IF(Q26=12,80,(IF(Q26=13,80,(IF(Q26=14,160,(IF(Q26=15,160,(IF(Q26=16,160,(IF(Q26=17,160,(IF(Q26=18,320,(IF(Q26=19,320,(IF(Q26=20,320,(IF(Q26=21,320,(IF(Q26=22,640,(IF(Q26=23,640,(IF(Q26=24,640,(IF(Q26=25,640,(IF(Q26=26,1280,(IF(Q26=27,1280,(IF(Q26=28,1280,(IF(Q26=29,1280,(IF(Q26=30,2560,(IF(Q26=31,2560,(IF(Q26=32,2560,(IF(Q26=33,2560,(IF(Q26=34,5120,(IF(Q26=35,5120,(IF(Q26=36,5120,(IF(Q26=37,5120,(IF(Q26=38,10240,(IF(Q26=39,10240,(IF(Q26=40,10240,"No endpoint"))))))))))))))))))))))))))))))))))))))))))))))))))))))))))))))))))))))))))))))))) -> 640 | V26: =IF(T26="25",0,(IF(T26="5",50,(IF(T26="75",25,0))))) -> 50 | W26: =50-V26 -> 0 | X26: =IF(T26="25",75,100) -> 100 | Y26: =X26-V26 -> 50 | Z26: =W26/Y26 -> 0 | AA26: =LOG10(2) -> 0.30103 | AB26: =Z26*AA26 -> 0 | AC26: =LOG10(U26) -> 2.80618 | AD26: =AB26+AC26 -> 2.80618 | AE26: =10^AD26 -> 640 | AF26: =ROUND(AE26,1) -> 640 | AG26: =IF(AF26<20,"<20",ROUND(AF26,0)) -> 640
B27: ='MN layout (2x)'!C23 -> 20 | C27: ='MN layout (2x)'!A23 -> 1678-066(122)_post_inf_visit | D27: ='MN layout (2x)'!B23 -> 1:20 | E27: ---- | F27: ---- | G27: ---- | H27: -++- | I27: -+-- | J27: ---+ | K27: ++++ | L27: ++++ | M27: ++++ | N27: ++++ | O27: ++++ | P27: ---- | Q27: {=SUMPRODUCT(LEN(E27:N27)-LEN(SUBSTITUTE(E27:N27,"-","")))} -> 20 | R27: =Q27/4 -> 5 | S27: {=_xlfn.TEXTSPLIT(R27,".",)} -> 5 | U27: =IF(Q27=0,10,(IF(Q27=1,10,(IF(Q27=2,20,(IF(Q27=3,20,(IF(Q27=4,20,(IF(Q27=5,20,(IF(Q27=6,40,(IF(Q27=7,40,(IF(Q27=8,40,(IF(Q27=9,40,(IF(Q27=10,80,(IF(Q27=11,80,(IF(Q27=12,80,(IF(Q27=13,80,(IF(Q27=14,160,(IF(Q27=15,160,(IF(Q27=16,160,(IF(Q27=17,160,(IF(Q27=18,320,(IF(Q27=19,320,(IF(Q27=20,320,(IF(Q27=21,320,(IF(Q27=22,640,(IF(Q27=23,640,(IF(Q27=24,640,(IF(Q27=25,640,(IF(Q27=26,1280,(IF(Q27=27,1280,(IF(Q27=28,1280,(IF(Q27=29,1280,(IF(Q27=30,2560,(IF(Q27=31,2560,(IF(Q27=32,2560,(IF(Q27=33,2560,(IF(Q27=34,5120,(IF(Q27=35,5120,(IF(Q27=36,5120,(IF(Q27=37,5120,(IF(Q27=38,10240,(IF(Q27=39,10240,(IF(Q27=40,10240,"No endpoint"))))))))))))))))))))))))))))))))))))))))))))))))))))))))))))))))))))))))))))))))) -> 320 | V27: =IF(T27="25",0,(IF(T27="5",50,(IF(T27="75",25,0))))) -> 0 | W27: =50-V27 -> 50 | X27: =IF(T27="25",75,100) -> 100 | Y27: =X27-V27 -> 100 | Z27: =W27/Y27 -> 0.5 | AA27: =LOG10(2) -> 0.30103 | AB27: =Z27*AA27 -> 0.150515 | AC27: =LOG10(U27) -> 2.50515 | AD27: =AB27+AC27 -> 2.655665 | AE27: =10^AD27 -> 452.54834 | AF27: =ROUND(AE27,1) -> 452.5 | AG27: =IF(AF27<20,"<20",ROUND(AF27,0)) -> 453
A28: P11 | B28: ='MN layout (2x)'!C24 -> 21 | C28: ='MN layout (2x)'!A24 -> 1678-070(126)_post_inf_visit | D28: ='MN layout (2x)'!B24 -> 1:20 | E28: ---- | F28: ---- | G28: ---- | H28: ---- | I28: --+- | J28: +--+ | K28: ++++ | L28: ++++ | M28: ++++ | N28: ++++ | O28: ++++ | P28: ---- | Q28: {=SUMPRODUCT(LEN(E28:N28)-LEN(SUBSTITUTE(E28:N28,"-","")))} -> 21 | R28: =Q28/4 -> 5.25 | S28: {=_xlfn.TEXTSPLIT(R28,".",)} -> 5 | T28: 25 | U28: =IF(Q28=0,10,(IF(Q28=1,10,(IF(Q28=2,20,(IF(Q28=3,20,(IF(Q28=4,20,(IF(Q28=5,20,(IF(Q28=6,40,(IF(Q28=7,40,(IF(Q28=8,40,(IF(Q28=9,40,(IF(Q28=10,80,(IF(Q28=11,80,(IF(Q28=12,80,(IF(Q28=13,80,(IF(Q28=14,160,(IF(Q28=15,160,(IF(Q28=16,160,(IF(Q28=17,160,(IF(Q28=18,320,(IF(Q28=19,320,(IF(Q28=20,320,(IF(Q28=21,320,(IF(Q28=22,640,(IF(Q28=23,640,(IF(Q28=24,640,(IF(Q28=25,640,(IF(Q28=26,1280,(IF(Q28=27,1280,(IF(Q28=28,1280,(IF(Q28=29,1280,(IF(Q28=30,2560,(IF(Q28=31,2560,(IF(Q28=32,2560,(IF(Q28=33,2560,(IF(Q28=34,5120,(IF(Q28=35,5120,(IF(Q28=36,5120,(IF(Q28=37,5120,(IF(Q28=38,10240,(IF(Q28=39,10240,(IF(Q28=40,10240,"No endpoint"))))))))))))))))))))))))))))))))))))))))))))))))))))))))))))))))))))))))))))))))) -> 320 | V28: =IF(T28="25",0,(IF(T28="5",50,(IF(T28="75",25,0))))) -> 0 | W28: =50-V28 -> 50 | X28: =IF(T28="25",75,100) -> 75 | Y28: =X28-V28 -> 75 | Z28: =W28/Y28 -> 0.66666667 | AA28: =LOG10(2) -> 0.30103 | AB28: =Z28*AA28 -> 0.20068666 | AC28: =LOG10(U28) -> 2.50515 | AD28: =AB28+AC28 -> 2.7058366 | AE28: =10^AD28 -> 507.96834 | AF28: =ROUND(AE28,1) -> 508 | AG28: =IF(AF28<20,"<20",ROUND(AF28,0)) -> 508
B29: ='MN layout (2x)'!C25 -> 22 | C29: ='MN layout (2x)'!A25 -> 1678-078(037)_post_inf_visit | D29: ='MN layout (2x)'!B25 -> 1:20 | E29: ---- | F29: ---- | G29: ---- | H29: --+- | I29: --++ | J29: ++-+ | K29: ++++ | L29: ++++ | M29: ++++ | N29: ++++ | O29: ++++ | P29: ---- | Q29: {=SUMPRODUCT(LEN(E29:N29)-LEN(SUBSTITUTE(E29:N29,"-","")))} -> 18 | R29: =Q29/4 -> 4.5 | S29: {=_xlfn.TEXTSPLIT(R29,".",)} -> 4 | T29: 5 | U29: =IF(Q29=0,10,(IF(Q29=1,10,(IF(Q29=2,20,(IF(Q29=3,20,(IF(Q29=4,20,(IF(Q29=5,20,(IF(Q29=6,40,(IF(Q29=7,40,(IF(Q29=8,40,(IF(Q29=9,40,(IF(Q29=10,80,(IF(Q29=11,80,(IF(Q29=12,80,(IF(Q29=13,80,(IF(Q29=14,160,(IF(Q29=15,160,(IF(Q29=16,160,(IF(Q29=17,160,(IF(Q29=18,320,(IF(Q29=19,320,(IF(Q29=20,320,(IF(Q29=21,320,(IF(Q29=22,640,(IF(Q29=23,640,(IF(Q29=24,640,(IF(Q29=25,640,(IF(Q29=26,1280,(IF(Q29=27,1280,(IF(Q29=28,1280,(IF(Q29=29,1280,(IF(Q29=30,2560,(IF(Q29=31,2560,(IF(Q29=32,2560,(IF(Q29=33,2560,(IF(Q29=34,5120,(IF(Q29=35,5120,(IF(Q29=36,5120,(IF(Q29=37,5120,(IF(Q29=38,10240,(IF(Q29=39,10240,(IF(Q29=40,10240,"No endpoint"))))))))))))))))))))))))))))))))))))))))))))))))))))))))))))))))))))))))))))))))) -> 320 | V29: =IF(T29="25",0,(IF(T29="5",50,(IF(T29="75",25,0))))) -> 50 | W29: =50-V29 -> 0 | X29: =IF(T29="25",75,100) -> 100 | Y29: =X29-V29 -> 50 | Z29: =W29/Y29 -> 0 | AA29: =LOG10(2) -> 0.30103 | AB29: =Z29*AA29 -> 0 | AC29: =LOG10(U29) -> 2.50515 | AD29: =AB29+AC29 -> 2.50515 | AE29: =10^AD29 -> 320 | AF29: =ROUND(AE29,1) -> 320 | AG29: =IF(AF29<20,"<20",ROUND(AF29,0)) -> 320
A30: P12 | B30: ='MN layout (2x)'!C26 -> 23 | C30: ='MN layout (2x)'!A26 -> 1678-090(144)_post_inf_visit | D30: ='MN layout (2x)'!B26 -> 1:20 | E30: ---- | F30: ---- | G30: ---- | H30: ---- | I30: ---- | J30: --++ | K30: +++- | L30: ++-+ | M30: ++++ | N30: ++++ | O30: ++++ | P30: ---- | Q30: {=SUMPRODUCT(LEN(E30:N30)-LEN(SUBSTITUTE(E30:N30,"-","")))} -> 24 | R30: =Q30/4 -> 6 | S30: {=_xlfn.TEXTSPLIT(R30,".",)} -> 6 | U30: =IF(Q30=0,10,(IF(Q30=1,10,(IF(Q30=2,20,(IF(Q30=3,20,(IF(Q30=4,20,(IF(Q30=5,20,(IF(Q30=6,40,(IF(Q30=7,40,(IF(Q30=8,40,(IF(Q30=9,40,(IF(Q30=10,80,(IF(Q30=11,80,(IF(Q30=12,80,(IF(Q30=13,80,(IF(Q30=14,160,(IF(Q30=15,160,(IF(Q30=16,160,(IF(Q30=17,160,(IF(Q30=18,320,(IF(Q30=19,320,(IF(Q30=20,320,(IF(Q30=21,320,(IF(Q30=22,640,(IF(Q30=23,640,(IF(Q30=24,640,(IF(Q30=25,640,(IF(Q30=26,1280,(IF(Q30=27,1280,(IF(Q30=28,1280,(IF(Q30=29,1280,(IF(Q30=30,2560,(IF(Q30=31,2560,(IF(Q30=32,2560,(IF(Q30=33,2560,(IF(Q30=34,5120,(IF(Q30=35,5120,(IF(Q30=36,5120,(IF(Q30=37,5120,(IF(Q30=38,10240,(IF(Q30=39,10240,(IF(Q30=40,10240,"No endpoint"))))))))))))))))))))))))))))))))))))))))))))))))))))))))))))))))))))))))))))))))) -> 640 | V30: =IF(T30="25",0,(IF(T30="5",50,(IF(T30="75",25,0))))) -> 0 | W30: =50-V30 -> 50 | X30: =IF(T30="25",75,100) -> 100 | Y30: =X30-V30 -> 100 | Z30: =W30/Y30 -> 0.5 | AA30: =LOG10(2) -> 0.30103 | AB30: =Z30*AA30 -> 0.150515 | AC30: =LOG10(U30) -> 2.80618 | AD30: =AB30+AC30 -> 2.956695 | AE30: =10^AD30 -> 905.09668 | AF30: =ROUND(AE30,1) -> 905.1 | AG30: =IF(AF30<20,"<20",ROUND(AF30,0)) -> 905
B31: ='MN layout (2x)'!C27 -> 24 | C31: ='MN layout (2x)'!A27 -> 1678-091(145)_post_inf_visit | D31: ='MN layout (2x)'!B27 -> 1:20 | E31: ---- | F31: ---- | G31: ---- | H31: ---- | I31: -+-- | J31: ++++ | K31: -+++ | L31: ++++ | M31: ++++ | N31: ++++ | O31: ++++ | P31: ---- | Q31: {=SUMPRODUCT(LEN(E31:N31)-LEN(SUBSTITUTE(E31:N31,"-","")))} -> 20 | R31: =Q31/4 -> 5 | S31: {=_xlfn.TEXTSPLIT(R31,".",)} -> 5 | U31: =IF(Q31=0,10,(IF(Q31=1,10,(IF(Q31=2,20,(IF(Q31=3,20,(IF(Q31=4,20,(IF(Q31=5,20,(IF(Q31=6,40,(IF(Q31=7,40,(IF(Q31=8,40,(IF(Q31=9,40,(IF(Q31=10,80,(IF(Q31=11,80,(IF(Q31=12,80,(IF(Q31=13,80,(IF(Q31=14,160,(IF(Q31=15,160,(IF(Q31=16,160,(IF(Q31=17,160,(IF(Q31=18,320,(IF(Q31=19,320,(IF(Q31=20,320,(IF(Q31=21,320,(IF(Q31=22,640,(IF(Q31=23,640,(IF(Q31=24,640,(IF(Q31=25,640,(IF(Q31=26,1280,(IF(Q31=27,1280,(IF(Q31=28,1280,(IF(Q31=29,1280,(IF(Q31=30,2560,(IF(Q31=31,2560,(IF(Q31=32,2560,(IF(Q31=33,2560,(IF(Q31=34,5120,(IF(Q31=35,5120,(IF(Q31=36,5120,(IF(Q31=37,5120,(IF(Q31=38,10240,(IF(Q31=39,10240,(IF(Q31=40,10240,"No endpoint"))))))))))))))))))))))))))))))))))))))))))))))))))))))))))))))))))))))))))))))))) -> 320 | V31: =IF(T31="25",0,(IF(T31="5",50,(IF(T31="75",25,0))))) -> 0 | W31: =50-V31 -> 50 | X31: =IF(T31="25",75,100) -> 100 | Y31: =X31-V31 -> 100 | Z31: =W31/Y31 -> 0.5 | AA31: =LOG10(2) -> 0.30103 | AB31: =Z31*AA31 -> 0.150515 | AC31: =LOG10(U31) -> 2.50515 | AD31: =AB31+AC31 -> 2.655665 | AE31: =10^AD31 -> 452.54834 | AF31: =ROUND(AE31,1) -> 452.5 | AG31: =IF(AF31<20,"<20",ROUND(AF31,0)) -> 453
A32: P13 | B32: ='MN layout (2x)'!C28 -> 25 | C32: ='MN layout (2x)'!A28 -> 1678-095(149)_post_inf_visit | D32: ='MN layout (2x)'!B28 -> 1:20 | E32: ---- | F32: ---- | G32: ---- | H32: ---- | I32: ---- | J32: ++++ | K32: ++++ | L32: ++++ | M32: ++++ | N32: ++++ | O32: ++++ | P32: ---- | Q32: {=SUMPRODUCT(LEN(E32:N32)-LEN(SUBSTITUTE(E32:N32,"-","")))} -> 20 | R32: =Q32/4 -> 5 | S32: {=_xlfn.TEXTSPLIT(R32,".",)} -> 5 | U32: =IF(Q32=0,10,(IF(Q32=1,10,(IF(Q32=2,20,(IF(Q32=3,20,(IF(Q32=4,20,(IF(Q32=5,20,(IF(Q32=6,40,(IF(Q32=7,40,(IF(Q32=8,40,(IF(Q32=9,40,(IF(Q32=10,80,(IF(Q32=11,80,(IF(Q32=12,80,(IF(Q32=13,80,(IF(Q32=14,160,(IF(Q32=15,160,(IF(Q32=16,160,(IF(Q32=17,160,(IF(Q32=18,320,(IF(Q32=19,320,(IF(Q32=20,320,(IF(Q32=21,320,(IF(Q32=22,640,(IF(Q32=23,640,(IF(Q32=24,640,(IF(Q32=25,640,(IF(Q32=26,1280,(IF(Q32=27,1280,(IF(Q32=28,1280,(IF(Q32=29,1280,(IF(Q32=30,2560,(IF(Q32=31,2560,(IF(Q32=32,2560,(IF(Q32=33,2560,(IF(Q32=34,5120,(IF(Q32=35,5120,(IF(Q32=36,5120,(IF(Q32=37,5120,(IF(Q32=38,10240,(IF(Q32=39,10240,(IF(Q32=40,10240,"No endpoint"))))))))))))))))))))))))))))))))))))))))))))))))))))))))))))))))))))))))))))))))) -> 320 | V32: =IF(T32="25",0,(IF(T32="5",50,(IF(T32="75",25,0))))) -> 0 | W32: =50-V32 -> 50 | X32: =IF(T32="25",75,100) -> 100 | Y32: =X32-V32 -> 100 | Z32: =W32/Y32 -> 0.5 | AA32: =LOG10(2) -> 0.30103 | AB32: =Z32*AA32 -> 0.150515 | AC32: =LOG10(U32) -> 2.50515 | AD32: =AB32+AC32 -> 2.655665 | AE32: =10^AD32 -> 452.54834 | AF32: =ROUND(AE32,1) -> 452.5 | AG32: =IF(AF32<20,"<20",ROUND(AF32,0)) -> 453
B33: ='MN layout (2x)'!C29 -> 26 | C33: ='MN layout (2x)'!A29 -> 1678-099(153)_post_inf_visit | D33: ='MN layout (2x)'!B29 -> 1:20 | E33: ---- | F33: ---- | G33: ---- | H33: ---- | I33: ---- | J33: --+- | K33: +++- | L33: ++++ | M33: ++++ | N33: +-++ | O33: ++++ | P33: ---- | Q33: {=SUMPRODUCT(LEN(E33:N33)-LEN(SUBSTITUTE(E33:N33,"-","")))} -> 25 | R33: =Q33/4 -> 6.25 | S33: {=_xlfn.TEXTSPLIT(R33,".",)} -> 6 | T33: 25 | U33: =IF(Q33=0,10,(IF(Q33=1,10,(IF(Q33=2,20,(IF(Q33=3,20,(IF(Q33=4,20,(IF(Q33=5,20,(IF(Q33=6,40,(IF(Q33=7,40,(IF(Q33=8,40,(IF(Q33=9,40,(IF(Q33=10,80,(IF(Q33=11,80,(IF(Q33=12,80,(IF(Q33=13,80,(IF(Q33=14,160,(IF(Q33=15,160,(IF(Q33=16,160,(IF(Q33=17,160,(IF(Q33=18,320,(IF(Q33=19,320,(IF(Q33=20,320,(IF(Q33=21,320,(IF(Q33=22,640,(IF(Q33=23,640,(IF(Q33=24,640,(IF(Q33=25,640,(IF(Q33=26,1280,(IF(Q33=27,1280,(IF(Q33=28,1280,(IF(Q33=29,1280,(IF(Q33=30,2560,(IF(Q33=31,2560,(IF(Q33=32,2560,(IF(Q33=33,2560,(IF(Q33=34,5120,(IF(Q33=35,5120,(IF(Q33=36,5120,(IF(Q33=37,5120,(IF(Q33=38,10240,(IF(Q33=39,10240,(IF(Q33=40,10240,"No endpoint"))))))))))))))))))))))))))))))))))))))))))))))))))))))))))))))))))))))))))))))))) -> 640 | V33: =IF(T33="25",0,(IF(T33="5",50,(IF(T33="75",25,0))))) -> 0 | W33: =50-V33 -> 50 | X33: =IF(T33="25",75,100) -> 75 | Y33: =X33-V33 -> 75 | Z33: =W33/Y33 -> 0.66666667 | AA33: =LOG10(2) -> 0.30103 | AB33: =Z33*AA33 -> 0.20068666 | AC33: =LOG10(U33) -> 2.80618 | AD33: =AB33+AC33 -> 3.0068666 | AE33: =10^AD33 -> 1015.9367 | AF33: =ROUND(AE33,1) -> 1015.9 | AG33: =IF(AF33<20,"<20",ROUND(AF33,0)) -> 1016
A34: P14 | B34: ='MN layout (2x)'!C30 -> 27 | C34: ='MN layout (2x)'!A30 -> 1678-SM_post_inf_visit | D34: ='MN layout (2x)'!B30 -> 1:20 | E34: ---- | F34: ---- | G34: --+- | H34: --+- | I34: -+++ | J34: -++- | K34: ++++ | L34: +++- | M34: ++++ | N34: ++++ | O34: ++++ | P34: ---- | Q34: {=SUMPRODUCT(LEN(E34:N34)-LEN(SUBSTITUTE(E34:N34,"-","")))} -> 18 | R34: =Q34/4 -> 4.5 | S34: {=_xlfn.TEXTSPLIT(R34,".",)} -> 4 | T34: 5 | U34: =IF(Q34=0,10,(IF(Q34=1,10,(IF(Q34=2,20,(IF(Q34=3,20,(IF(Q34=4,20,(IF(Q34=5,20,(IF(Q34=6,40,(IF(Q34=7,40,(IF(Q34=8,40,(IF(Q34=9,40,(IF(Q34=10,80,(IF(Q34=11,80,(IF(Q34=12,80,(IF(Q34=13,80,(IF(Q34=14,160,(IF(Q34=15,160,(IF(Q34=16,160,(IF(Q34=17,160,(IF(Q34=18,320,(IF(Q34=19,320,(IF(Q34=20,320,(IF(Q34=21,320,(IF(Q34=22,640,(IF(Q34=23,640,(IF(Q34=24,640,(IF(Q34=25,640,(IF(Q34=26,1280,(IF(Q34=27,1280,(IF(Q34=28,1280,(IF(Q34=29,1280,(IF(Q34=30,2560,(IF(Q34=31,2560,(IF(Q34=32,2560,(IF(Q34=33,2560,(IF(Q34=34,5120,(IF(Q34=35,5120,(IF(Q34=36,5120,(IF(Q34=37,5120,(IF(Q34=38,10240,(IF(Q34=39,10240,(IF(Q34=40,10240,"No endpoint"))))))))))))))))))))))))))))))))))))))))))))))))))))))))))))))))))))))))))))))))) -> 320 | V34: =IF(T34="25",0,(IF(T34="5",50,(IF(T34="75",25,0))))) -> 50 | W34: =50-V34 -> 0 | X34: =IF(T34="25",75,100) -> 100 | Y34: =X34-V34 -> 50 | Z34: =W34/Y34 -> 0 | AA34: =LOG10(2) -> 0.30103 | AB34: =Z34*AA34 -> 0 | AC34: =LOG10(U34) -> 2.50515 | AD34: =AB34+AC34 -> 2.50515 | AE34: =10^AD34 -> 320 | AF34: =ROUND(AE34,1) -> 320 | AG34: =IF(AF34<20,"<20",ROUND(AF34,0)) -> 320
B35: ='MN layout (2x)'!C31 -> 28 | C35: ='MN layout (2x)'!A31 -> NIBSC 21/338 | D35: ='MN layout (2x)'!B31 -> 1:20 | E35: ---- | F35: ---- | G35: ---- | H35: ---- | I35: ---- | J35: ---- | K35: -++- | L35: -+++ | M35: ++++ | N35: +-++ | O35: ++++ | P35: ---- | Q35: {=SUMPRODUCT(LEN(E35:N35)-LEN(SUBSTITUTE(E35:N35,"-","")))} -> 28 | R35: =Q35/4 -> 7 | S35: {=_xlfn.TEXTSPLIT(R35,".",)} -> 7 | U35: =IF(Q35=0,10,(IF(Q35=1,10,(IF(Q35=2,20,(IF(Q35=3,20,(IF(Q35=4,20,(IF(Q35=5,20,(IF(Q35=6,40,(IF(Q35=7,40,(IF(Q35=8,40,(IF(Q35=9,40,(IF(Q35=10,80,(IF(Q35=11,80,(IF(Q35=12,80,(IF(Q35=13,80,(IF(Q35=14,160,(IF(Q35=15,160,(IF(Q35=16,160,(IF(Q35=17,160,(IF(Q35=18,320,(IF(Q35=19,320,(IF(Q35=20,320,(IF(Q35=21,320,(IF(Q35=22,640,(IF(Q35=23,640,(IF(Q35=24,640,(IF(Q35=25,640,(IF(Q35=26,1280,(IF(Q35=27,1280,(IF(Q35=28,1280,(IF(Q35=29,1280,(IF(Q35=30,2560,(IF(Q35=31,2560,(IF(Q35=32,2560,(IF(Q35=33,2560,(IF(Q35=34,5120,(IF(Q35=35,5120,(IF(Q35=36,5120,(IF(Q35=37,5120,(IF(Q35=38,10240,(IF(Q35=39,10240,(IF(Q35=40,10240,"No endpoint"))))))))))))))))))))))))))))))))))))))))))))))))))))))))))))))))))))))))))))))))) -> 1280 | V35: =IF(T35="25",0,(IF(T35="5",50,(IF(T35="75",25,0))))) -> 0 | W35: =50-V35 -> 50 | X35: =IF(T35="25",75,100) -> 100 | Y35: =X35-V35 -> 100 | Z35: =W35/Y35 -> 0.5 | AA35: =LOG10(2) -> 0.30103 | AB35: =Z35*AA35 -> 0.150515 | AC35: =LOG10(U35) -> 3.10721 | AD35: =AB35+AC35 -> 3.257725 | AE35: =10^AD35 -> 1810.1934 | AF35: =ROUND(AE35,1) -> 1810.2 | AG35: =IF(AF35<20,"<20",ROUND(AF35,0)) -> 1810
A36: P15 | B36: ='MN layout (2x)'!C32 -> 29 | C36: ='MN layout (2x)'!A32 -> NIBSC 20/142 | D36: ='MN layout (2x)'!B32 -> 1:20 | E36: ++++ | F36: ++++ | G36: ++++ | H36: ++++ | I36: ++++ | J36: ++++ | K36: ++++ | L36: ++++ | M36: ++++ | N36: ++++ | O36: ++++ | P36: ---- | Q36: {=SUMPRODUCT(LEN(E36:N36)-LEN(SUBSTITUTE(E36:N36,"-","")))} -> 0 | R36: =Q36/4 -> 0 | S36: {=_xlfn.TEXTSPLIT(R36,".",)} -> 0 | U36: =IF(Q36=0,10,(IF(Q36=1,10,(IF(Q36=2,20,(IF(Q36=3,20,(IF(Q36=4,20,(IF(Q36=5,20,(IF(Q36=6,40,(IF(Q36=7,40,(IF(Q36=8,40,(IF(Q36=9,40,(IF(Q36=10,80,(IF(Q36=11,80,(IF(Q36=12,80,(IF(Q36=13,80,(IF(Q36=14,160,(IF(Q36=15,160,(IF(Q36=16,160,(IF(Q36=17,160,(IF(Q36=18,320,(IF(Q36=19,320,(IF(Q36=20,320,(IF(Q36=21,320,(IF(Q36=22,640,(IF(Q36=23,640,(IF(Q36=24,640,(IF(Q36=25,640,(IF(Q36=26,1280,(IF(Q36=27,1280,(IF(Q36=28,1280,(IF(Q36=29,1280,(IF(Q36=30,2560,(IF(Q36=31,2560,(IF(Q36=32,2560,(IF(Q36=33,2560,(IF(Q36=34,5120,(IF(Q36=35,5120,(IF(Q36=36,5120,(IF(Q36=37,5120,(IF(Q36=38,10240,(IF(Q36=39,10240,(IF(Q36=40,10240,"No endpoint"))))))))))))))))))))))))))))))))))))))))))))))))))))))))))))))))))))))))))))))))) -> 10 | V36: =IF(T36="25",0,(IF(T36="5",50,(IF(T36="75",25,0))))) -> 0 | W36: =50-V36 -> 50 | X36: =IF(T36="25",75,100) -> 100 | Y36: =X36-V36 -> 100 | Z36: =W36/Y36 -> 0.5 | AA36: =LOG10(2) -> 0.30103 | AB36: =Z36*AA36 -> 0.150515 | AC36: =LOG10(U36) -> 1 | AD36: =AB36+AC36 -> 1.150515 | AE36: =10^AD36 -> 14.142136 | AF36: =ROUND(AE36,1) -> 14.1 | AG36: =IF(AF36<20,"<20",ROUND(AF36,0)) -> <20
B37: ='MN layout (2x)'!C33 -> 30 | C37: ='MN layout (2x)'!A33 -> Neg 4 | D37: ='MN layout (2x)'!B33 -> 1:20 | E37: ++++ | F37: -+++ | G37: ++++ | H37: ++++ | I37: ++++ | J37: ++++ | K37: ++++ | L37: ++++ | M37: ++++ | N37: ++++ | O37: ++++ | P37: ---- | Q37: {=SUMPRODUCT(LEN(E37:N37)-LEN(SUBSTITUTE(E37:N37,"-","")))} -> 1 | R37: =Q37/4 -> 0.25 | S37: {=_xlfn.TEXTSPLIT(R37,".",)} -> 0 | T37: 25 | U37: =IF(Q37=0,10,(IF(Q37=1,10,(IF(Q37=2,20,(IF(Q37=3,20,(IF(Q37=4,20,(IF(Q37=5,20,(IF(Q37=6,40,(IF(Q37=7,40,(IF(Q37=8,40,(IF(Q37=9,40,(IF(Q37=10,80,(IF(Q37=11,80,(IF(Q37=12,80,(IF(Q37=13,80,(IF(Q37=14,160,(IF(Q37=15,160,(IF(Q37=16,160,(IF(Q37=17,160,(IF(Q37=18,320,(IF(Q37=19,320,(IF(Q37=20,320,(IF(Q37=21,320,(IF(Q37=22,640,(IF(Q37=23,640,(IF(Q37=24,640,(IF(Q37=25,640,(IF(Q37=26,1280,(IF(Q37=27,1280,(IF(Q37=28,1280,(IF(Q37=29,1280,(IF(Q37=30,2560,(IF(Q37=31,2560,(IF(Q37=32,2560,(IF(Q37=33,2560,(IF(Q37=34,5120,(IF(Q37=35,5120,(IF(Q37=36,5120,(IF(Q37=37,5120,(IF(Q37=38,10240,(IF(Q37=39,10240,(IF(Q37=40,10240,"No endpoint"))))))))))))))))))))))))))))))))))))))))))))))))))))))))))))))))))))))))))))))))) -> 10 | V37: =IF(T37="25",0,(IF(T37="5",50,(IF(T37="75",25,0))))) -> 0 | W37: =50-V37 -> 50 | X37: =IF(T37="25",75,100) -> 75 | Y37: =X37-V37 -> 75 | Z37: =W37/Y37 -> 0.66666667 | AA37: =LOG10(2) -> 0.30103 | AB37: =Z37*AA37 -> 0.20068666 | AC37: =LOG10(U37) -> 1 | AD37: =AB37+AC37 -> 1.2006867 | AE37: =10^AD37 -> 15.874011 | AF37: =ROUND(AE37,1) -> 15.9 | AG37: =IF(AF37<20,"<20",ROUND(AF37,0)) -> <20
A39: Back titration: need 3.3 (2.8-3.8) | D39: 0 | E39: -1 | F39: -2 | G39: -3 | H39: -4 | I39: -5 | J39: TCID50 | K39: TCID50/ml
C40: Normal method 1 | D40: ++++ | E40: ++++ | F40: --++ | G40: ---- | H40: ---- | I40: ---- | J40: 2 | K40: =J40+1.7 -> 3.7
C41: Normal method 2 | D41: ++++ | E41: ++++ | F41: ---+ | G41: ---- | H41: ---- | I41: ---- | J41: 1.75 | K41: =J41+1.7 -> 3.45
C42: Back titre + wash | D42: ++++ | E42: ---+ | F42: ---- | G42: ---- | H42: ---- | I42: ---- | J42: 0.75 | K42: =J42+1.7 -> 2.45
C43: David's method | D43: ++++ | E43: +++- | F43: ---- | G43: ---- | H43: ---- | I43: ---- | J43: 1.25 | K43: =J43+1.6 -> 2.85
...

Sheet MN results 2
A1: SARS_COV_2 MN | F1: Date of experiment: | G1: 03.07.24 | K1: Day 5 read: | L1: 08.07.24 | P1: ='MN layout (2x)'!R1 -> FM
A3: + = CPE; - = no CPE; C = contamination assumed neg; C = contamination assumed pos; * = non-CPE rounding of cells; ? = unsure what on earth is happening | W3: DO NOT CHANGE EQUATIONS
U4: enter data | V4: enter data | X4: enter data | AC4: 4'
A5: Plate # | B5: Neut ID | C5: Sample | D5: Starting dilution | E5: 20 | F5: 40 | G5: 80 | H5: 160 | I5: 320 | J5: 640 | K5: 1280 | L5: 2560 | M5: 5120 | N5: 10240 | O5: Virus control | P5: Cell control | Q5: Count "-"s | R5: n/4 | S5: text split | U5: "0" | V5: "1" | W5: 1' | X5: "2" | Y5: 2' | Z5: 1'/2' | AA5: "4" | AB5: 3' | AC5: log10("0") | AD5: 3'+4' | AE5: 10^(3'+4') | AF5: round to 1dp | AG5: MN titre
E7: 1 | F7: 2 | G7: 3 | H7: 4 | I7: 5 | J7: 6 | K7: 7 | L7: 8 | M7: 9 | N7: 10 | O7: 11 | P7: 12 | U7: dil<50% | V7: % +ve @dil<50 | W7: 50-"1" | X7: % +ve @dil>50 | Y7: "2"-"1" | Z7: "3" | AA7: log2 | AB7: "3"*"4" | AC7: log dil<50%
A8: P1 | B8: ='MN layout (2x)'!C4 -> 1 | C8: ='MN layout (2x)'!A4 -> High 3 | D8: ='MN layout (2x)'!B4 -> 1:20 | E8: ---- | F8: ---- | G8: ---- | H8: ---- | I8: +--- | J8: --++ | K8: ++++ | L8: ++++ | M8: ++++ | N8: +++- | O8: ++++ | P8: ---- | Q8: {=SUMPRODUCT(LEN(E8:N8)-LEN(SUBSTITUTE(E8:N8,"-","")))} -> 22 | R8: =Q8/4 -> 5.5 | S8: {=_xlfn.TEXTSPLIT(R8,".",)} -> 5 | T8: 5 | U8: =IF(Q8=0,10,(IF(Q8=1,10,(IF(Q8=2,20,(IF(Q8=3,20,(IF(Q8=4,20,(IF(Q8=5,20,(IF(Q8=6,40,(IF(Q8=7,40,(IF(Q8=8,40,(IF(Q8=9,40,(IF(Q8=10,80,(IF(Q8=11,80,(IF(Q8=12,80,(IF(Q8=13,80,(IF(Q8=14,160,(IF(Q8=15,160,(IF(Q8=16,160,(IF(Q8=17,160,(IF(Q8=18,320,(IF(Q8=19,320,(IF(Q8=20,320,(IF(Q8=21,320,(IF(Q8=22,640,(IF(Q8=23,640,(IF(Q8=24,640,(IF(Q8=25,640,(IF(Q8=26,1280,(IF(Q8=27,1280,(IF(Q8=28,1280,(IF(Q8=29,1280,(IF(Q8=30,2560,(IF(Q8=31,2560,(IF(Q8=32,2560,(IF(Q8=33,2560,(IF(Q8=34,5120,(IF(Q8=35,5120,(IF(Q8=36,5120,(IF(Q8=37,5120,(IF(Q8=38,10240,(IF(Q8=39,10240,(IF(Q8=40,10240,"No endpoint"))))))))))))))))))))))))))))))))))))))))))))))))))))))))))))))))))))))))))))))))) -> 640 | V8: =IF(T8="25",0,(IF(T8="5",50,(IF(T8="75",25,0))))) -> 50 | W8: =50-V8 -> 0 | X8: =IF(T8="25",75,100) -> 100 | Y8: =X8-V8 -> 50 | Z8: =W8/Y8 -> 0 | AA8: =LOG10(2) -> 0.30103 | AB8: =Z8*AA8 -> 0 | AC8: =LOG10(U8) -> 2.80618 | AD8: =AB8+AC8 -> 2.80618 | AE8: =10^AD8 -> 640 | AF8: =ROUND(AE8,1) -> 640 | AG8: =IF(AF8<20,"<20",ROUND(AF8,0)) -> 640
B9: ='MN layout (2x)'!C5 -> 2 | C9: ='MN layout (2x)'!A5 -> 1678-044_pv2 | D9: ='MN layout (2x)'!B5 -> 1:20 | E9: -+++ | F9: ---- | G9: ++-- | H9: ++-+ | I9: ++++ | J9: +-++ | K9: ++++ | L9: ++++ | M9: ++++ | N9: ++++ | O9: ++++ | P9: ---- | Q9: {=SUMPRODUCT(LEN(E9:N9)-LEN(SUBSTITUTE(E9:N9,"-","")))} -> 9 | R9: =Q9/4 -> 2.25 | S9: {=_xlfn.TEXTSPLIT(R9,".",)} -> 2 | T9: 25 | U9: =IF(Q9=0,10,(IF(Q9=1,10,(IF(Q9=2,20,(IF(Q9=3,20,(IF(Q9=4,20,(IF(Q9=5,20,(IF(Q9=6,40,(IF(Q9=7,40,(IF(Q9=8,40,(IF(Q9=9,40,(IF(Q9=10,80,(IF(Q9=11,80,(IF(Q9=12,80,(IF(Q9=13,80,(IF(Q9=14,160,(IF(Q9=15,160,(IF(Q9=16,160,(IF(Q9=17,160,(IF(Q9=18,320,(IF(Q9=19,320,(IF(Q9=20,320,(IF(Q9=21,320,(IF(Q9=22,640,(IF(Q9=23,640,(IF(Q9=24,640,(IF(Q9=25,640,(IF(Q9=26,1280,(IF(Q9=27,1280,(IF(Q9=28,1280,(IF(Q9=29,1280,(IF(Q9=30,2560,(IF(Q9=31,2560,(IF(Q9=32,2560,(IF(Q9=33,2560,(IF(Q9=34,5120,(IF(Q9=35,5120,(IF(Q9=36,5120,(IF(Q9=37,5120,(IF(Q9=38,10240,(IF(Q9=39,10240,(IF(Q9=40,10240,"No endpoint"))))))))))))))))))))))))))))))))))))))))))))))))))))))))))))))))))))))))))))))))) -> 40 | V9: =IF(T9="25",0,(IF(T9="5",50,(IF(T9="75",25,0))))) -> 0 | W9: =50-V9 -> 50 | X9: =IF(T9="25",75,100) -> 75 | Y9: =X9-V9 -> 75 | Z9: =W9/Y9 -> 0.66666667 | AA9: =LOG10(2) -> 0.30103 | AB9: =Z9*AA9 -> 0.20068666 | AC9: =LOG10(U9) -> 1.60206 | AD9: =AB9+AC9 -> 1.8027467 | AE9: =10^AD9 -> 63.496042 | AF9: =ROUND(AE9,1) -> 63.5 | AG9: =IF(AF9<20,"<20",ROUND(AF9,0)) -> 64
A10: P2 | B10: ='MN layout (2x)'!C6 -> 3 | C10: ='MN layout (2x)'!A6 -> 1678-044_PB1 | D10: ='MN layout (2x)'!B6 -> 1:20 | E10: ---- | F10: ---- | G10: ---- | H10: ---- | I10: ---- | J10: +--- | K10: ---+ | L10: ++++ | M10: ++++ | N10: ++++ | O10: ++++ | P10: ---- | Q10: {=SUMPRODUCT(LEN(E10:N10)-LEN(SUBSTITUTE(E10:N10,"-","")))} -> 26 | R10: =Q10/4 -> 6.5 | S10: {=_xlfn.TEXTSPLIT(R10,".",)} -> 6 | T10: 5 | U10: =IF(Q10=0,10,(IF(Q10=1,10,(IF(Q10=2,20,(IF(Q10=3,20,(IF(Q10=4,20,(IF(Q10=5,20,(IF(Q10=6,40,(IF(Q10=7,40,(IF(Q10=8,40,(IF(Q10=9,40,(IF(Q10=10,80,(IF(Q10=11,80,(IF(Q10=12,80,(IF(Q10=13,80,(IF(Q10=14,160,(IF(Q10=15,160,(IF(Q10=16,160,(IF(Q10=17,160,(IF(Q10=18,320,(IF(Q10=19,320,(IF(Q10=20,320,(IF(Q10=21,320,(IF(Q10=22,640,(IF(Q10=23,640,(IF(Q10=24,640,(IF(Q10=25,640,(IF(Q10=26,1280,(IF(Q10=27,1280,(IF(Q10=28,1280,(IF(Q10=29,1280,(IF(Q10=30,2560,(IF(Q10=31,2560,(IF(Q10=32,2560,(IF(Q10=33,2560,(IF(Q10=34,5120,(IF(Q10=35,5120,(IF(Q10=36,5120,(IF(Q10=37,5120,(IF(Q10=38,10240,(IF(Q10=39,10240,(IF(Q10=40,10240,"No endpoint"))))))))))))))))))))))))))))))))))))))))))))))))))))))))))))))))))))))))))))))))) -> 1280 | V10: =IF(T10="25",0,(IF(T10="5",50,(IF(T10="75",25,0))))) -> 50 | W10: =50-V10 -> 0 | X10: =IF(T10="25",75,100) -> 100 | Y10: =X10-V10 -> 50 | Z10: =W10/Y10 -> 0 | AA10: =LOG10(2) -> 0.30103 | AB10: =Z10*AA10 -> 0 | AC10: =LOG10(U10) -> 3.10721 | AD10: =AB10+AC10 -> 3.10721 | AE10: =10^AD10 -> 1280 | AF10: =ROUND(AE10,1) -> 1280 | AG10: =IF(AF10<20,"<20",ROUND(AF10,0)) -> 1280
B11: ='MN layout (2x)'!C7 -> 4 | C11: ='MN layout (2x)'!A7 -> 1678-047_pv2 | D11: ='MN layout (2x)'!B7 -> 1:20 | E11: +--- | F11: --+- | G11: -++- | H11: +--- | I11: -++- | J11: +--+ | K11: -+++ | L11: ++-+ | M11: -+++ | N11: ++-+ | O11: ++++ | P11: ---- | Q11: {=SUMPRODUCT(LEN(E11:N11)-LEN(SUBSTITUTE(E11:N11,"-","")))} -> 19 | R11: =Q11/4 -> 4.75 | S11: {=_xlfn.TEXTSPLIT(R11,".",)} -> 4 | T11: 75 | U11: =IF(Q11=0,10,(IF(Q11=1,10,(IF(Q11=2,20,(IF(Q11=3,20,(IF(Q11=4,20,(IF(Q11=5,20,(IF(Q11=6,40,(IF(Q11=7,40,(IF(Q11=8,40,(IF(Q11=9,40,(IF(Q11=10,80,(IF(Q11=11,80,(IF(Q11=12,80,(IF(Q11=13,80,(IF(Q11=14,160,(IF(Q11=15,160,(IF(Q11=16,160,(IF(Q11=17,160,(IF(Q11=18,320,(IF(Q11=19,320,(IF(Q11=20,320,(IF(Q11=21,320,(IF(Q11=22,640,(IF(Q11=23,640,(IF(Q11=24,640,(IF(Q11=25,640,(IF(Q11=26,1280,(IF(Q11=27,1280,(IF(Q11=28,1280,(IF(Q11=29,1280,(IF(Q11=30,2560,(IF(Q11=31,2560,(IF(Q11=32,2560,(IF(Q11=33,2560,(IF(Q11=34,5120,(IF(Q11=35,5120,(IF(Q11=36,5120,(IF(Q11=37,5120,(IF(Q11=38,10240,(IF(Q11=39,10240,(IF(Q11=40,10240,"No endpoint"))))))))))))))))))))))))))))))))))))))))))))))))))))))))))))))))))))))))))))))))) -> 320 | V11: =IF(T11="25",0,(IF(T11="5",50,(IF(T11="75",25,0))))) -> 25 | W11: =50-V11 -> 25 | X11: =IF(T11="25",75,100) -> 100 | Y11: =X11-V11 -> 75 | Z11: =W11/Y11 -> 0.33333333 | AA11: =LOG10(2) -> 0.30103 | AB11: =Z11*AA11 -> 0.10034333 | AC11: =LOG10(U11) -> 2.50515 | AD11: =AB11+AC11 -> 2.6054933 | AE11: =10^AD11 -> 403.17474 | AF11: =ROUND(AE11,1) -> 403.2 | AG11: =IF(AF11<20,"<20",ROUND(AF11,0)) -> 403
